<?xml version="1.0"?><robot name="pepe">
	<link name="0">
		<visual>
			<geometry>
				<box size="1.4422837028967659 1.4422837028967659 1.4422837028967659"/>
			</geometry>
		</visual>
		<collision>
			<geometry>
				<box size="1.4422837028967659 1.4422837028967659 1.4422837028967659"/>
			</geometry>
		</collision>
		<inertial>
			<mass value="0.27104816631840367"/>
			<inertia ixx="0.03" ixy="0" ixz="0" iyx="0" iyy="0.03" izz="0.03"/>
		</inertial>
	</link>
	<link name="11">
		<visual>
			<geometry>
				<box size="1.6793171824580089 1.6793171824580089 1.6793171824580089"/>
			</geometry>
		</visual>
		<collision>
			<geometry>
				<box size="1.6793171824580089 1.6793171824580089 1.6793171824580089"/>
			</geometry>
		</collision>
		<inertial>
			<mass value="0.0973956192422835"/>
			<inertia ixx="0.03" ixy="0" ixz="0" iyx="0" iyy="0.03" izz="0.03"/>
		</inertial>
	</link>
	<link name="22">
		<visual>
			<geometry>
				<cylinder length="0.007805902181151625" radius="0.6768572436038026"/>
			</geometry>
		</visual>
		<collision>
			<geometry>
				<cylinder length="0.007805902181151625" radius="0.6768572436038026"/>
			</geometry>
		</collision>
		<inertial>
			<mass value="0.011234846404056805"/>
			<inertia ixx="0.03" ixy="0" ixz="0" iyx="0" iyy="0.03" izz="0.03"/>
		</inertial>
	</link>
	<link name="13">
		<visual>
			<geometry>
				<box size="1.6793171824580089 1.6793171824580089 1.6793171824580089"/>
			</geometry>
		</visual>
		<collision>
			<geometry>
				<box size="1.6793171824580089 1.6793171824580089 1.6793171824580089"/>
			</geometry>
		</collision>
		<inertial>
			<mass value="0.0973956192422835"/>
			<inertia ixx="0.03" ixy="0" ixz="0" iyx="0" iyy="0.03" izz="0.03"/>
		</inertial>
	</link>
	<link name="24">
		<visual>
			<geometry>
				<cylinder length="0.007805902181151625" radius="0.6768572436038026"/>
			</geometry>
		</visual>
		<collision>
			<geometry>
				<cylinder length="0.007805902181151625" radius="0.6768572436038026"/>
			</geometry>
		</collision>
		<inertial>
			<mass value="0.011234846404056805"/>
			<inertia ixx="0.03" ixy="0" ixz="0" iyx="0" iyy="0.03" izz="0.03"/>
		</inertial>
	</link>
	<link name="15">
		<visual>
			<geometry>
				<box size="1.6793171824580089 1.6793171824580089 1.6793171824580089"/>
			</geometry>
		</visual>
		<collision>
			<geometry>
				<box size="1.6793171824580089 1.6793171824580089 1.6793171824580089"/>
			</geometry>
		</collision>
		<inertial>
			<mass value="0.0973956192422835"/>
			<inertia ixx="0.03" ixy="0" ixz="0" iyx="0" iyy="0.03" izz="0.03"/>
		</inertial>
	</link>
	<link name="26">
		<visual>
			<geometry>
				<cylinder length="0.007805902181151625" radius="0.6768572436038026"/>
			</geometry>
		</visual>
		<collision>
			<geometry>
				<cylinder length="0.007805902181151625" radius="0.6768572436038026"/>
			</geometry>
		</collision>
		<inertial>
			<mass value="0.011234846404056805"/>
			<inertia ixx="0.03" ixy="0" ixz="0" iyx="0" iyy="0.03" izz="0.03"/>
		</inertial>
	</link>
	<joint name="11_to_0" type="revolute">
		<parent link="0"/>
		<child link="11"/>
		<axis xyz="0 1 0"/>
		<limit effort="1" lower="3.1415" upper="-3.1415" velocity="1"/>
		<origin rpy="10.31429885092539 3.815832006601965 6.257160855174368" xyz="0.13373472983671186 0.29737354379756853 0.6621108903792577"/>
	</joint>
	<joint name="22_to_11" type="revolute">
		<parent link="11"/>
		<child link="22"/>
		<axis xyz="0 1 0"/>
		<limit effort="1" lower="3.1415" upper="-3.1415" velocity="1"/>
		<origin rpy="5.67668857185224 4.826414115524076 5.02613044416073" xyz="0.44640277226779224 0.35296108024940176 0.5997270566348657"/>
	</joint>
	<joint name="13_to_0" type="revolute">
		<parent link="0"/>
		<child link="13"/>
		<axis xyz="0 1 0"/>
		<limit effort="1" lower="3.1415" upper="-3.1415" velocity="1"/>
		<origin rpy="15.471448276388085 3.815832006601965 6.257160855174368" xyz="0.13373472983671186 0.29737354379756853 0.6621108903792577"/>
	</joint>
	<joint name="24_to_13" type="revolute">
		<parent link="13"/>
		<child link="24"/>
		<axis xyz="0 1 0"/>
		<limit effort="1" lower="3.1415" upper="-3.1415" velocity="1"/>
		<origin rpy="5.67668857185224 4.826414115524076 5.02613044416073" xyz="0.44640277226779224 0.35296108024940176 0.5997270566348657"/>
	</joint>
	<joint name="15_to_0" type="revolute">
		<parent link="0"/>
		<child link="15"/>
		<axis xyz="0 1 0"/>
		<limit effort="1" lower="3.1415" upper="-3.1415" velocity="1"/>
		<origin rpy="20.62859770185078 3.815832006601965 6.257160855174368" xyz="0.13373472983671186 0.29737354379756853 0.6621108903792577"/>
	</joint>
	<joint name="26_to_15" type="revolute">
		<parent link="15"/>
		<child link="26"/>
		<axis xyz="0 1 0"/>
		<limit effort="1" lower="3.1415" upper="-3.1415" velocity="1"/>
		<origin rpy="5.67668857185224 4.826414115524076 5.02613044416073" xyz="0.44640277226779224 0.35296108024940176 0.5997270566348657"/>
	</joint>
</robot>
