<?xml version="1.0"?><robot name="pepe">
	<link name="0">
		<visual>
			<geometry>
				<box size="1.6322319111498327 1.6322319111498327 1.6322319111498327"/>
			</geometry>
		</visual>
		<collision>
			<geometry>
				<box size="1.6322319111498327 1.6322319111498327 1.6322319111498327"/>
			</geometry>
		</collision>
		<inertial>
			<mass value="0.002428490064569883"/>
			<inertia ixx="0.03" iyy="0.03" izz="0.03" ixy="0" ixz="0" iyx="0"/>
		</inertial>
	</link>
	<link name="11">
		<visual>
			<geometry>
				<cylinder length="1.9998" radius="0.9999"/>
			</geometry>
		</visual>
		<collision>
			<geometry>
				<cylinder length="1.9998" radius="0.9999"/>
			</geometry>
		</collision>
		<inertial>
			<mass value="6.281300540076709"/>
			<inertia ixx="0.03" iyy="0.03" izz="0.03" ixy="0" ixz="0" iyx="0"/>
		</inertial>
	</link>
	<link name="12">
		<visual>
			<geometry>
				<cylinder length="1.9998" radius="0.9999"/>
			</geometry>
		</visual>
		<collision>
			<geometry>
				<cylinder length="1.9998" radius="0.9999"/>
			</geometry>
		</collision>
		<inertial>
			<mass value="6.281300540076709"/>
			<inertia ixx="0.03" iyy="0.03" izz="0.03" ixy="0" ixz="0" iyx="0"/>
		</inertial>
	</link>
	<joint name="11_to_0" type="revolute">
		<parent link="0"/>
		<child link="11"/>
		<axis xyz="0 0 1"/>
		<limit effort="1" upper="-3.1415" lower="3.1415" velocity="1"/>
		<origin rpy="12.565113977297736 3.600420847499156 2.982406471367985" xyz="0.06904317670072035 0.9999 0.8026076203724806"/>
	</joint>
	<joint name="12_to_0" type="revolute">
		<parent link="0"/>
		<child link="12"/>
		<axis xyz="0 0 1"/>
		<limit effort="1" upper="-3.1415" lower="3.1415" velocity="1"/>
		<origin rpy="18.847670965946605 3.600420847499156 2.982406471367985" xyz="0.06904317670072035 0.9999 0.8026076203724806"/>
	</joint>
</robot>
