<?xml version="1.0"?><robot name="pepe">
	<link name="0">
		<visual>
			<geometry>
				<cylinder length="1.620270057947925" radius="0.33162976685398904"/>
			</geometry>
		</visual>
		<collision>
			<geometry>
				<cylinder length="1.620270057947925" radius="0.33162976685398904"/>
			</geometry>
		</collision>
		<inertial>
			<mass value="0.5598146897605916"/>
			<inertia ixx="0.03" ixy="0" ixz="0" iyx="0" iyy="0.03" izz="0.03"/>
		</inertial>
	</link>
	<link name="11">
		<visual>
			<geometry>
				<cylinder length="0.9839968931008223" radius="0.20489524701403172"/>
			</geometry>
		</visual>
		<collision>
			<geometry>
				<cylinder length="0.9839968931008223" radius="0.20489524701403172"/>
			</geometry>
		</collision>
		<inertial>
			<mass value="0.12977987995971638"/>
			<inertia ixx="0.03" ixy="0" ixz="0" iyx="0" iyy="0.03" izz="0.03"/>
		</inertial>
	</link>
	<link name="22">
		<visual>
			<geometry>
				<cylinder length="0.4992144062714243" radius="0.6776198890848838"/>
			</geometry>
		</visual>
		<collision>
			<geometry>
				<cylinder length="0.4992144062714243" radius="0.6776198890848838"/>
			</geometry>
		</collision>
		<inertial>
			<mass value="0.7201272939641289"/>
			<inertia ixx="0.03" ixy="0" ixz="0" iyx="0" iyy="0.03" izz="0.03"/>
		</inertial>
	</link>
	<joint name="11_to_0" type="revolute">
		<parent link="0"/>
		<child link="11"/>
		<axis xyz="0 0 1"/>
		<limit effort="1" lower="3.1415" upper="-3.1415" velocity="1"/>
		<origin rpy="7.300555879291387 4.803052681363918 0.9855001705750575" xyz="0.5433014881025203 0.10072810275251065 0.7749395988028834"/>
	</joint>
	<joint name="22_to_0" type="revolute">
		<parent link="0"/>
		<child link="22"/>
		<axis xyz="0 1 0"/>
		<limit effort="1" lower="3.1415" upper="-3.1415" velocity="1"/>
		<origin rpy="5.558661727454597 2.5399956445500633 4.67058598033998" xyz="0.9999 0.7238567635861478 0.5522377714191339"/>
	</joint>
</robot>
