<?xml version="1.0"?><robot name="pepe">
	<link name="0">
		<visual>
			<geometry>
				<sphere radius="0.9847132714172134"/>
			</geometry>
		</visual>
		<collision>
			<geometry>
				<sphere radius="0.9847132714172134"/>
			</geometry>
		</collision>
		<inertial>
			<mass value="2.433658513279265"/>
			<inertia ixx="0.03" iyy="0.03" izz="0.03" ixy="0" ixz="0" iyx="0"/>
		</inertial>
	</link>
	<link name="11">
		<visual>
			<geometry>
				<sphere radius="0.5970695760447879"/>
			</geometry>
		</visual>
		<collision>
			<geometry>
				<sphere radius="0.5970695760447879"/>
			</geometry>
		</collision>
		<inertial>
			<mass value="0.8862245479835859"/>
			<inertia ixx="0.03" iyy="0.03" izz="0.03" ixy="0" ixz="0" iyx="0"/>
		</inertial>
	</link>
	<link name="22">
		<visual>
			<geometry>
				<sphere radius="0.914551099716554"/>
			</geometry>
		</visual>
		<collision>
			<geometry>
				<sphere radius="0.914551099716554"/>
			</geometry>
		</collision>
		<inertial>
			<mass value="2.3615934314283016"/>
			<inertia ixx="0.03" iyy="0.03" izz="0.03" ixy="0" ixz="0" iyx="0"/>
		</inertial>
	</link>
	<link name="33">
		<visual>
			<geometry>
				<sphere radius="0.41767174834899823"/>
			</geometry>
		</visual>
		<collision>
			<geometry>
				<sphere radius="0.41767174834899823"/>
			</geometry>
		</collision>
		<inertial>
			<mass value="0.9179345154310158"/>
			<inertia ixx="0.03" iyy="0.03" izz="0.03" ixy="0" ixz="0" iyx="0"/>
		</inertial>
	</link>
	<link name="44">
		<visual>
			<geometry>
				<sphere radius="0.05432080736827971"/>
			</geometry>
		</visual>
		<collision>
			<geometry>
				<sphere radius="0.05432080736827971"/>
			</geometry>
		</collision>
		<inertial>
			<mass value="0.015791304247651492"/>
			<inertia ixx="0.03" iyy="0.03" izz="0.03" ixy="0" ixz="0" iyx="0"/>
		</inertial>
	</link>
	<link name="55">
		<visual>
			<geometry>
				<sphere radius="0.546790288102742"/>
			</geometry>
		</visual>
		<collision>
			<geometry>
				<sphere radius="0.546790288102742"/>
			</geometry>
		</collision>
		<inertial>
			<mass value="1.0517241171501588"/>
			<inertia ixx="0.03" iyy="0.03" izz="0.03" ixy="0" ixz="0" iyx="0"/>
		</inertial>
	</link>
	<link name="56">
		<visual>
			<geometry>
				<sphere radius="0.546790288102742"/>
			</geometry>
		</visual>
		<collision>
			<geometry>
				<sphere radius="0.546790288102742"/>
			</geometry>
		</collision>
		<inertial>
			<mass value="1.0517241171501588"/>
			<inertia ixx="0.03" iyy="0.03" izz="0.03" ixy="0" ixz="0" iyx="0"/>
		</inertial>
	</link>
	<link name="57">
		<visual>
			<geometry>
				<sphere radius="0.546790288102742"/>
			</geometry>
		</visual>
		<collision>
			<geometry>
				<sphere radius="0.546790288102742"/>
			</geometry>
		</collision>
		<inertial>
			<mass value="1.0517241171501588"/>
			<inertia ixx="0.03" iyy="0.03" izz="0.03" ixy="0" ixz="0" iyx="0"/>
		</inertial>
	</link>
	<link name="48">
		<visual>
			<geometry>
				<sphere radius="0.05432080736827971"/>
			</geometry>
		</visual>
		<collision>
			<geometry>
				<sphere radius="0.05432080736827971"/>
			</geometry>
		</collision>
		<inertial>
			<mass value="0.015791304247651492"/>
			<inertia ixx="0.03" iyy="0.03" izz="0.03" ixy="0" ixz="0" iyx="0"/>
		</inertial>
	</link>
	<link name="59">
		<visual>
			<geometry>
				<sphere radius="0.546790288102742"/>
			</geometry>
		</visual>
		<collision>
			<geometry>
				<sphere radius="0.546790288102742"/>
			</geometry>
		</collision>
		<inertial>
			<mass value="1.0517241171501588"/>
			<inertia ixx="0.03" iyy="0.03" izz="0.03" ixy="0" ixz="0" iyx="0"/>
		</inertial>
	</link>
	<link name="510">
		<visual>
			<geometry>
				<sphere radius="0.546790288102742"/>
			</geometry>
		</visual>
		<collision>
			<geometry>
				<sphere radius="0.546790288102742"/>
			</geometry>
		</collision>
		<inertial>
			<mass value="1.0517241171501588"/>
			<inertia ixx="0.03" iyy="0.03" izz="0.03" ixy="0" ixz="0" iyx="0"/>
		</inertial>
	</link>
	<link name="511">
		<visual>
			<geometry>
				<sphere radius="0.546790288102742"/>
			</geometry>
		</visual>
		<collision>
			<geometry>
				<sphere radius="0.546790288102742"/>
			</geometry>
		</collision>
		<inertial>
			<mass value="1.0517241171501588"/>
			<inertia ixx="0.03" iyy="0.03" izz="0.03" ixy="0" ixz="0" iyx="0"/>
		</inertial>
	</link>
	<link name="412">
		<visual>
			<geometry>
				<sphere radius="0.05432080736827971"/>
			</geometry>
		</visual>
		<collision>
			<geometry>
				<sphere radius="0.05432080736827971"/>
			</geometry>
		</collision>
		<inertial>
			<mass value="0.015791304247651492"/>
			<inertia ixx="0.03" iyy="0.03" izz="0.03" ixy="0" ixz="0" iyx="0"/>
		</inertial>
	</link>
	<link name="513">
		<visual>
			<geometry>
				<sphere radius="0.546790288102742"/>
			</geometry>
		</visual>
		<collision>
			<geometry>
				<sphere radius="0.546790288102742"/>
			</geometry>
		</collision>
		<inertial>
			<mass value="1.0517241171501588"/>
			<inertia ixx="0.03" iyy="0.03" izz="0.03" ixy="0" ixz="0" iyx="0"/>
		</inertial>
	</link>
	<link name="514">
		<visual>
			<geometry>
				<sphere radius="0.546790288102742"/>
			</geometry>
		</visual>
		<collision>
			<geometry>
				<sphere radius="0.546790288102742"/>
			</geometry>
		</collision>
		<inertial>
			<mass value="1.0517241171501588"/>
			<inertia ixx="0.03" iyy="0.03" izz="0.03" ixy="0" ixz="0" iyx="0"/>
		</inertial>
	</link>
	<link name="515">
		<visual>
			<geometry>
				<sphere radius="0.546790288102742"/>
			</geometry>
		</visual>
		<collision>
			<geometry>
				<sphere radius="0.546790288102742"/>
			</geometry>
		</collision>
		<inertial>
			<mass value="1.0517241171501588"/>
			<inertia ixx="0.03" iyy="0.03" izz="0.03" ixy="0" ixz="0" iyx="0"/>
		</inertial>
	</link>
	<link name="216">
		<visual>
			<geometry>
				<sphere radius="0.914551099716554"/>
			</geometry>
		</visual>
		<collision>
			<geometry>
				<sphere radius="0.914551099716554"/>
			</geometry>
		</collision>
		<inertial>
			<mass value="2.3615934314283016"/>
			<inertia ixx="0.03" iyy="0.03" izz="0.03" ixy="0" ixz="0" iyx="0"/>
		</inertial>
	</link>
	<link name="317">
		<visual>
			<geometry>
				<sphere radius="0.41767174834899823"/>
			</geometry>
		</visual>
		<collision>
			<geometry>
				<sphere radius="0.41767174834899823"/>
			</geometry>
		</collision>
		<inertial>
			<mass value="0.9179345154310158"/>
			<inertia ixx="0.03" iyy="0.03" izz="0.03" ixy="0" ixz="0" iyx="0"/>
		</inertial>
	</link>
	<link name="418">
		<visual>
			<geometry>
				<sphere radius="0.05432080736827971"/>
			</geometry>
		</visual>
		<collision>
			<geometry>
				<sphere radius="0.05432080736827971"/>
			</geometry>
		</collision>
		<inertial>
			<mass value="0.015791304247651492"/>
			<inertia ixx="0.03" iyy="0.03" izz="0.03" ixy="0" ixz="0" iyx="0"/>
		</inertial>
	</link>
	<link name="519">
		<visual>
			<geometry>
				<sphere radius="0.546790288102742"/>
			</geometry>
		</visual>
		<collision>
			<geometry>
				<sphere radius="0.546790288102742"/>
			</geometry>
		</collision>
		<inertial>
			<mass value="1.0517241171501588"/>
			<inertia ixx="0.03" iyy="0.03" izz="0.03" ixy="0" ixz="0" iyx="0"/>
		</inertial>
	</link>
	<link name="520">
		<visual>
			<geometry>
				<sphere radius="0.546790288102742"/>
			</geometry>
		</visual>
		<collision>
			<geometry>
				<sphere radius="0.546790288102742"/>
			</geometry>
		</collision>
		<inertial>
			<mass value="1.0517241171501588"/>
			<inertia ixx="0.03" iyy="0.03" izz="0.03" ixy="0" ixz="0" iyx="0"/>
		</inertial>
	</link>
	<link name="521">
		<visual>
			<geometry>
				<sphere radius="0.546790288102742"/>
			</geometry>
		</visual>
		<collision>
			<geometry>
				<sphere radius="0.546790288102742"/>
			</geometry>
		</collision>
		<inertial>
			<mass value="1.0517241171501588"/>
			<inertia ixx="0.03" iyy="0.03" izz="0.03" ixy="0" ixz="0" iyx="0"/>
		</inertial>
	</link>
	<link name="422">
		<visual>
			<geometry>
				<sphere radius="0.05432080736827971"/>
			</geometry>
		</visual>
		<collision>
			<geometry>
				<sphere radius="0.05432080736827971"/>
			</geometry>
		</collision>
		<inertial>
			<mass value="0.015791304247651492"/>
			<inertia ixx="0.03" iyy="0.03" izz="0.03" ixy="0" ixz="0" iyx="0"/>
		</inertial>
	</link>
	<link name="523">
		<visual>
			<geometry>
				<sphere radius="0.546790288102742"/>
			</geometry>
		</visual>
		<collision>
			<geometry>
				<sphere radius="0.546790288102742"/>
			</geometry>
		</collision>
		<inertial>
			<mass value="1.0517241171501588"/>
			<inertia ixx="0.03" iyy="0.03" izz="0.03" ixy="0" ixz="0" iyx="0"/>
		</inertial>
	</link>
	<link name="524">
		<visual>
			<geometry>
				<sphere radius="0.546790288102742"/>
			</geometry>
		</visual>
		<collision>
			<geometry>
				<sphere radius="0.546790288102742"/>
			</geometry>
		</collision>
		<inertial>
			<mass value="1.0517241171501588"/>
			<inertia ixx="0.03" iyy="0.03" izz="0.03" ixy="0" ixz="0" iyx="0"/>
		</inertial>
	</link>
	<link name="525">
		<visual>
			<geometry>
				<sphere radius="0.546790288102742"/>
			</geometry>
		</visual>
		<collision>
			<geometry>
				<sphere radius="0.546790288102742"/>
			</geometry>
		</collision>
		<inertial>
			<mass value="1.0517241171501588"/>
			<inertia ixx="0.03" iyy="0.03" izz="0.03" ixy="0" ixz="0" iyx="0"/>
		</inertial>
	</link>
	<link name="426">
		<visual>
			<geometry>
				<sphere radius="0.05432080736827971"/>
			</geometry>
		</visual>
		<collision>
			<geometry>
				<sphere radius="0.05432080736827971"/>
			</geometry>
		</collision>
		<inertial>
			<mass value="0.015791304247651492"/>
			<inertia ixx="0.03" iyy="0.03" izz="0.03" ixy="0" ixz="0" iyx="0"/>
		</inertial>
	</link>
	<link name="527">
		<visual>
			<geometry>
				<sphere radius="0.546790288102742"/>
			</geometry>
		</visual>
		<collision>
			<geometry>
				<sphere radius="0.546790288102742"/>
			</geometry>
		</collision>
		<inertial>
			<mass value="1.0517241171501588"/>
			<inertia ixx="0.03" iyy="0.03" izz="0.03" ixy="0" ixz="0" iyx="0"/>
		</inertial>
	</link>
	<link name="528">
		<visual>
			<geometry>
				<sphere radius="0.546790288102742"/>
			</geometry>
		</visual>
		<collision>
			<geometry>
				<sphere radius="0.546790288102742"/>
			</geometry>
		</collision>
		<inertial>
			<mass value="1.0517241171501588"/>
			<inertia ixx="0.03" iyy="0.03" izz="0.03" ixy="0" ixz="0" iyx="0"/>
		</inertial>
	</link>
	<link name="529">
		<visual>
			<geometry>
				<sphere radius="0.546790288102742"/>
			</geometry>
		</visual>
		<collision>
			<geometry>
				<sphere radius="0.546790288102742"/>
			</geometry>
		</collision>
		<inertial>
			<mass value="1.0517241171501588"/>
			<inertia ixx="0.03" iyy="0.03" izz="0.03" ixy="0" ixz="0" iyx="0"/>
		</inertial>
	</link>
	<link name="230">
		<visual>
			<geometry>
				<sphere radius="0.914551099716554"/>
			</geometry>
		</visual>
		<collision>
			<geometry>
				<sphere radius="0.914551099716554"/>
			</geometry>
		</collision>
		<inertial>
			<mass value="2.3615934314283016"/>
			<inertia ixx="0.03" iyy="0.03" izz="0.03" ixy="0" ixz="0" iyx="0"/>
		</inertial>
	</link>
	<link name="331">
		<visual>
			<geometry>
				<sphere radius="0.41767174834899823"/>
			</geometry>
		</visual>
		<collision>
			<geometry>
				<sphere radius="0.41767174834899823"/>
			</geometry>
		</collision>
		<inertial>
			<mass value="0.9179345154310158"/>
			<inertia ixx="0.03" iyy="0.03" izz="0.03" ixy="0" ixz="0" iyx="0"/>
		</inertial>
	</link>
	<link name="432">
		<visual>
			<geometry>
				<sphere radius="0.05432080736827971"/>
			</geometry>
		</visual>
		<collision>
			<geometry>
				<sphere radius="0.05432080736827971"/>
			</geometry>
		</collision>
		<inertial>
			<mass value="0.015791304247651492"/>
			<inertia ixx="0.03" iyy="0.03" izz="0.03" ixy="0" ixz="0" iyx="0"/>
		</inertial>
	</link>
	<link name="533">
		<visual>
			<geometry>
				<sphere radius="0.546790288102742"/>
			</geometry>
		</visual>
		<collision>
			<geometry>
				<sphere radius="0.546790288102742"/>
			</geometry>
		</collision>
		<inertial>
			<mass value="1.0517241171501588"/>
			<inertia ixx="0.03" iyy="0.03" izz="0.03" ixy="0" ixz="0" iyx="0"/>
		</inertial>
	</link>
	<link name="534">
		<visual>
			<geometry>
				<sphere radius="0.546790288102742"/>
			</geometry>
		</visual>
		<collision>
			<geometry>
				<sphere radius="0.546790288102742"/>
			</geometry>
		</collision>
		<inertial>
			<mass value="1.0517241171501588"/>
			<inertia ixx="0.03" iyy="0.03" izz="0.03" ixy="0" ixz="0" iyx="0"/>
		</inertial>
	</link>
	<link name="535">
		<visual>
			<geometry>
				<sphere radius="0.546790288102742"/>
			</geometry>
		</visual>
		<collision>
			<geometry>
				<sphere radius="0.546790288102742"/>
			</geometry>
		</collision>
		<inertial>
			<mass value="1.0517241171501588"/>
			<inertia ixx="0.03" iyy="0.03" izz="0.03" ixy="0" ixz="0" iyx="0"/>
		</inertial>
	</link>
	<link name="436">
		<visual>
			<geometry>
				<sphere radius="0.05432080736827971"/>
			</geometry>
		</visual>
		<collision>
			<geometry>
				<sphere radius="0.05432080736827971"/>
			</geometry>
		</collision>
		<inertial>
			<mass value="0.015791304247651492"/>
			<inertia ixx="0.03" iyy="0.03" izz="0.03" ixy="0" ixz="0" iyx="0"/>
		</inertial>
	</link>
	<link name="537">
		<visual>
			<geometry>
				<sphere radius="0.546790288102742"/>
			</geometry>
		</visual>
		<collision>
			<geometry>
				<sphere radius="0.546790288102742"/>
			</geometry>
		</collision>
		<inertial>
			<mass value="1.0517241171501588"/>
			<inertia ixx="0.03" iyy="0.03" izz="0.03" ixy="0" ixz="0" iyx="0"/>
		</inertial>
	</link>
	<link name="538">
		<visual>
			<geometry>
				<sphere radius="0.546790288102742"/>
			</geometry>
		</visual>
		<collision>
			<geometry>
				<sphere radius="0.546790288102742"/>
			</geometry>
		</collision>
		<inertial>
			<mass value="1.0517241171501588"/>
			<inertia ixx="0.03" iyy="0.03" izz="0.03" ixy="0" ixz="0" iyx="0"/>
		</inertial>
	</link>
	<link name="539">
		<visual>
			<geometry>
				<sphere radius="0.546790288102742"/>
			</geometry>
		</visual>
		<collision>
			<geometry>
				<sphere radius="0.546790288102742"/>
			</geometry>
		</collision>
		<inertial>
			<mass value="1.0517241171501588"/>
			<inertia ixx="0.03" iyy="0.03" izz="0.03" ixy="0" ixz="0" iyx="0"/>
		</inertial>
	</link>
	<link name="440">
		<visual>
			<geometry>
				<sphere radius="0.05432080736827971"/>
			</geometry>
		</visual>
		<collision>
			<geometry>
				<sphere radius="0.05432080736827971"/>
			</geometry>
		</collision>
		<inertial>
			<mass value="0.015791304247651492"/>
			<inertia ixx="0.03" iyy="0.03" izz="0.03" ixy="0" ixz="0" iyx="0"/>
		</inertial>
	</link>
	<link name="541">
		<visual>
			<geometry>
				<sphere radius="0.546790288102742"/>
			</geometry>
		</visual>
		<collision>
			<geometry>
				<sphere radius="0.546790288102742"/>
			</geometry>
		</collision>
		<inertial>
			<mass value="1.0517241171501588"/>
			<inertia ixx="0.03" iyy="0.03" izz="0.03" ixy="0" ixz="0" iyx="0"/>
		</inertial>
	</link>
	<link name="542">
		<visual>
			<geometry>
				<sphere radius="0.546790288102742"/>
			</geometry>
		</visual>
		<collision>
			<geometry>
				<sphere radius="0.546790288102742"/>
			</geometry>
		</collision>
		<inertial>
			<mass value="1.0517241171501588"/>
			<inertia ixx="0.03" iyy="0.03" izz="0.03" ixy="0" ixz="0" iyx="0"/>
		</inertial>
	</link>
	<link name="543">
		<visual>
			<geometry>
				<sphere radius="0.546790288102742"/>
			</geometry>
		</visual>
		<collision>
			<geometry>
				<sphere radius="0.546790288102742"/>
			</geometry>
		</collision>
		<inertial>
			<mass value="1.0517241171501588"/>
			<inertia ixx="0.03" iyy="0.03" izz="0.03" ixy="0" ixz="0" iyx="0"/>
		</inertial>
	</link>
	<link name="144">
		<visual>
			<geometry>
				<sphere radius="0.5970695760447879"/>
			</geometry>
		</visual>
		<collision>
			<geometry>
				<sphere radius="0.5970695760447879"/>
			</geometry>
		</collision>
		<inertial>
			<mass value="0.8862245479835859"/>
			<inertia ixx="0.03" iyy="0.03" izz="0.03" ixy="0" ixz="0" iyx="0"/>
		</inertial>
	</link>
	<link name="245">
		<visual>
			<geometry>
				<sphere radius="0.914551099716554"/>
			</geometry>
		</visual>
		<collision>
			<geometry>
				<sphere radius="0.914551099716554"/>
			</geometry>
		</collision>
		<inertial>
			<mass value="2.3615934314283016"/>
			<inertia ixx="0.03" iyy="0.03" izz="0.03" ixy="0" ixz="0" iyx="0"/>
		</inertial>
	</link>
	<link name="346">
		<visual>
			<geometry>
				<sphere radius="0.41767174834899823"/>
			</geometry>
		</visual>
		<collision>
			<geometry>
				<sphere radius="0.41767174834899823"/>
			</geometry>
		</collision>
		<inertial>
			<mass value="0.9179345154310158"/>
			<inertia ixx="0.03" iyy="0.03" izz="0.03" ixy="0" ixz="0" iyx="0"/>
		</inertial>
	</link>
	<link name="447">
		<visual>
			<geometry>
				<sphere radius="0.05432080736827971"/>
			</geometry>
		</visual>
		<collision>
			<geometry>
				<sphere radius="0.05432080736827971"/>
			</geometry>
		</collision>
		<inertial>
			<mass value="0.015791304247651492"/>
			<inertia ixx="0.03" iyy="0.03" izz="0.03" ixy="0" ixz="0" iyx="0"/>
		</inertial>
	</link>
	<link name="548">
		<visual>
			<geometry>
				<sphere radius="0.546790288102742"/>
			</geometry>
		</visual>
		<collision>
			<geometry>
				<sphere radius="0.546790288102742"/>
			</geometry>
		</collision>
		<inertial>
			<mass value="1.0517241171501588"/>
			<inertia ixx="0.03" iyy="0.03" izz="0.03" ixy="0" ixz="0" iyx="0"/>
		</inertial>
	</link>
	<link name="549">
		<visual>
			<geometry>
				<sphere radius="0.546790288102742"/>
			</geometry>
		</visual>
		<collision>
			<geometry>
				<sphere radius="0.546790288102742"/>
			</geometry>
		</collision>
		<inertial>
			<mass value="1.0517241171501588"/>
			<inertia ixx="0.03" iyy="0.03" izz="0.03" ixy="0" ixz="0" iyx="0"/>
		</inertial>
	</link>
	<link name="550">
		<visual>
			<geometry>
				<sphere radius="0.546790288102742"/>
			</geometry>
		</visual>
		<collision>
			<geometry>
				<sphere radius="0.546790288102742"/>
			</geometry>
		</collision>
		<inertial>
			<mass value="1.0517241171501588"/>
			<inertia ixx="0.03" iyy="0.03" izz="0.03" ixy="0" ixz="0" iyx="0"/>
		</inertial>
	</link>
	<link name="451">
		<visual>
			<geometry>
				<sphere radius="0.05432080736827971"/>
			</geometry>
		</visual>
		<collision>
			<geometry>
				<sphere radius="0.05432080736827971"/>
			</geometry>
		</collision>
		<inertial>
			<mass value="0.015791304247651492"/>
			<inertia ixx="0.03" iyy="0.03" izz="0.03" ixy="0" ixz="0" iyx="0"/>
		</inertial>
	</link>
	<link name="552">
		<visual>
			<geometry>
				<sphere radius="0.546790288102742"/>
			</geometry>
		</visual>
		<collision>
			<geometry>
				<sphere radius="0.546790288102742"/>
			</geometry>
		</collision>
		<inertial>
			<mass value="1.0517241171501588"/>
			<inertia ixx="0.03" iyy="0.03" izz="0.03" ixy="0" ixz="0" iyx="0"/>
		</inertial>
	</link>
	<link name="553">
		<visual>
			<geometry>
				<sphere radius="0.546790288102742"/>
			</geometry>
		</visual>
		<collision>
			<geometry>
				<sphere radius="0.546790288102742"/>
			</geometry>
		</collision>
		<inertial>
			<mass value="1.0517241171501588"/>
			<inertia ixx="0.03" iyy="0.03" izz="0.03" ixy="0" ixz="0" iyx="0"/>
		</inertial>
	</link>
	<link name="554">
		<visual>
			<geometry>
				<sphere radius="0.546790288102742"/>
			</geometry>
		</visual>
		<collision>
			<geometry>
				<sphere radius="0.546790288102742"/>
			</geometry>
		</collision>
		<inertial>
			<mass value="1.0517241171501588"/>
			<inertia ixx="0.03" iyy="0.03" izz="0.03" ixy="0" ixz="0" iyx="0"/>
		</inertial>
	</link>
	<link name="455">
		<visual>
			<geometry>
				<sphere radius="0.05432080736827971"/>
			</geometry>
		</visual>
		<collision>
			<geometry>
				<sphere radius="0.05432080736827971"/>
			</geometry>
		</collision>
		<inertial>
			<mass value="0.015791304247651492"/>
			<inertia ixx="0.03" iyy="0.03" izz="0.03" ixy="0" ixz="0" iyx="0"/>
		</inertial>
	</link>
	<link name="556">
		<visual>
			<geometry>
				<sphere radius="0.546790288102742"/>
			</geometry>
		</visual>
		<collision>
			<geometry>
				<sphere radius="0.546790288102742"/>
			</geometry>
		</collision>
		<inertial>
			<mass value="1.0517241171501588"/>
			<inertia ixx="0.03" iyy="0.03" izz="0.03" ixy="0" ixz="0" iyx="0"/>
		</inertial>
	</link>
	<link name="557">
		<visual>
			<geometry>
				<sphere radius="0.546790288102742"/>
			</geometry>
		</visual>
		<collision>
			<geometry>
				<sphere radius="0.546790288102742"/>
			</geometry>
		</collision>
		<inertial>
			<mass value="1.0517241171501588"/>
			<inertia ixx="0.03" iyy="0.03" izz="0.03" ixy="0" ixz="0" iyx="0"/>
		</inertial>
	</link>
	<link name="558">
		<visual>
			<geometry>
				<sphere radius="0.546790288102742"/>
			</geometry>
		</visual>
		<collision>
			<geometry>
				<sphere radius="0.546790288102742"/>
			</geometry>
		</collision>
		<inertial>
			<mass value="1.0517241171501588"/>
			<inertia ixx="0.03" iyy="0.03" izz="0.03" ixy="0" ixz="0" iyx="0"/>
		</inertial>
	</link>
	<link name="259">
		<visual>
			<geometry>
				<sphere radius="0.914551099716554"/>
			</geometry>
		</visual>
		<collision>
			<geometry>
				<sphere radius="0.914551099716554"/>
			</geometry>
		</collision>
		<inertial>
			<mass value="2.3615934314283016"/>
			<inertia ixx="0.03" iyy="0.03" izz="0.03" ixy="0" ixz="0" iyx="0"/>
		</inertial>
	</link>
	<link name="360">
		<visual>
			<geometry>
				<sphere radius="0.41767174834899823"/>
			</geometry>
		</visual>
		<collision>
			<geometry>
				<sphere radius="0.41767174834899823"/>
			</geometry>
		</collision>
		<inertial>
			<mass value="0.9179345154310158"/>
			<inertia ixx="0.03" iyy="0.03" izz="0.03" ixy="0" ixz="0" iyx="0"/>
		</inertial>
	</link>
	<link name="461">
		<visual>
			<geometry>
				<sphere radius="0.05432080736827971"/>
			</geometry>
		</visual>
		<collision>
			<geometry>
				<sphere radius="0.05432080736827971"/>
			</geometry>
		</collision>
		<inertial>
			<mass value="0.015791304247651492"/>
			<inertia ixx="0.03" iyy="0.03" izz="0.03" ixy="0" ixz="0" iyx="0"/>
		</inertial>
	</link>
	<link name="562">
		<visual>
			<geometry>
				<sphere radius="0.546790288102742"/>
			</geometry>
		</visual>
		<collision>
			<geometry>
				<sphere radius="0.546790288102742"/>
			</geometry>
		</collision>
		<inertial>
			<mass value="1.0517241171501588"/>
			<inertia ixx="0.03" iyy="0.03" izz="0.03" ixy="0" ixz="0" iyx="0"/>
		</inertial>
	</link>
	<link name="563">
		<visual>
			<geometry>
				<sphere radius="0.546790288102742"/>
			</geometry>
		</visual>
		<collision>
			<geometry>
				<sphere radius="0.546790288102742"/>
			</geometry>
		</collision>
		<inertial>
			<mass value="1.0517241171501588"/>
			<inertia ixx="0.03" iyy="0.03" izz="0.03" ixy="0" ixz="0" iyx="0"/>
		</inertial>
	</link>
	<link name="564">
		<visual>
			<geometry>
				<sphere radius="0.546790288102742"/>
			</geometry>
		</visual>
		<collision>
			<geometry>
				<sphere radius="0.546790288102742"/>
			</geometry>
		</collision>
		<inertial>
			<mass value="1.0517241171501588"/>
			<inertia ixx="0.03" iyy="0.03" izz="0.03" ixy="0" ixz="0" iyx="0"/>
		</inertial>
	</link>
	<link name="465">
		<visual>
			<geometry>
				<sphere radius="0.05432080736827971"/>
			</geometry>
		</visual>
		<collision>
			<geometry>
				<sphere radius="0.05432080736827971"/>
			</geometry>
		</collision>
		<inertial>
			<mass value="0.015791304247651492"/>
			<inertia ixx="0.03" iyy="0.03" izz="0.03" ixy="0" ixz="0" iyx="0"/>
		</inertial>
	</link>
	<link name="566">
		<visual>
			<geometry>
				<sphere radius="0.546790288102742"/>
			</geometry>
		</visual>
		<collision>
			<geometry>
				<sphere radius="0.546790288102742"/>
			</geometry>
		</collision>
		<inertial>
			<mass value="1.0517241171501588"/>
			<inertia ixx="0.03" iyy="0.03" izz="0.03" ixy="0" ixz="0" iyx="0"/>
		</inertial>
	</link>
	<link name="567">
		<visual>
			<geometry>
				<sphere radius="0.546790288102742"/>
			</geometry>
		</visual>
		<collision>
			<geometry>
				<sphere radius="0.546790288102742"/>
			</geometry>
		</collision>
		<inertial>
			<mass value="1.0517241171501588"/>
			<inertia ixx="0.03" iyy="0.03" izz="0.03" ixy="0" ixz="0" iyx="0"/>
		</inertial>
	</link>
	<link name="568">
		<visual>
			<geometry>
				<sphere radius="0.546790288102742"/>
			</geometry>
		</visual>
		<collision>
			<geometry>
				<sphere radius="0.546790288102742"/>
			</geometry>
		</collision>
		<inertial>
			<mass value="1.0517241171501588"/>
			<inertia ixx="0.03" iyy="0.03" izz="0.03" ixy="0" ixz="0" iyx="0"/>
		</inertial>
	</link>
	<link name="469">
		<visual>
			<geometry>
				<sphere radius="0.05432080736827971"/>
			</geometry>
		</visual>
		<collision>
			<geometry>
				<sphere radius="0.05432080736827971"/>
			</geometry>
		</collision>
		<inertial>
			<mass value="0.015791304247651492"/>
			<inertia ixx="0.03" iyy="0.03" izz="0.03" ixy="0" ixz="0" iyx="0"/>
		</inertial>
	</link>
	<link name="570">
		<visual>
			<geometry>
				<sphere radius="0.546790288102742"/>
			</geometry>
		</visual>
		<collision>
			<geometry>
				<sphere radius="0.546790288102742"/>
			</geometry>
		</collision>
		<inertial>
			<mass value="1.0517241171501588"/>
			<inertia ixx="0.03" iyy="0.03" izz="0.03" ixy="0" ixz="0" iyx="0"/>
		</inertial>
	</link>
	<link name="571">
		<visual>
			<geometry>
				<sphere radius="0.546790288102742"/>
			</geometry>
		</visual>
		<collision>
			<geometry>
				<sphere radius="0.546790288102742"/>
			</geometry>
		</collision>
		<inertial>
			<mass value="1.0517241171501588"/>
			<inertia ixx="0.03" iyy="0.03" izz="0.03" ixy="0" ixz="0" iyx="0"/>
		</inertial>
	</link>
	<link name="572">
		<visual>
			<geometry>
				<sphere radius="0.546790288102742"/>
			</geometry>
		</visual>
		<collision>
			<geometry>
				<sphere radius="0.546790288102742"/>
			</geometry>
		</collision>
		<inertial>
			<mass value="1.0517241171501588"/>
			<inertia ixx="0.03" iyy="0.03" izz="0.03" ixy="0" ixz="0" iyx="0"/>
		</inertial>
	</link>
	<link name="273">
		<visual>
			<geometry>
				<sphere radius="0.914551099716554"/>
			</geometry>
		</visual>
		<collision>
			<geometry>
				<sphere radius="0.914551099716554"/>
			</geometry>
		</collision>
		<inertial>
			<mass value="2.3615934314283016"/>
			<inertia ixx="0.03" iyy="0.03" izz="0.03" ixy="0" ixz="0" iyx="0"/>
		</inertial>
	</link>
	<link name="374">
		<visual>
			<geometry>
				<sphere radius="0.41767174834899823"/>
			</geometry>
		</visual>
		<collision>
			<geometry>
				<sphere radius="0.41767174834899823"/>
			</geometry>
		</collision>
		<inertial>
			<mass value="0.9179345154310158"/>
			<inertia ixx="0.03" iyy="0.03" izz="0.03" ixy="0" ixz="0" iyx="0"/>
		</inertial>
	</link>
	<link name="475">
		<visual>
			<geometry>
				<sphere radius="0.05432080736827971"/>
			</geometry>
		</visual>
		<collision>
			<geometry>
				<sphere radius="0.05432080736827971"/>
			</geometry>
		</collision>
		<inertial>
			<mass value="0.015791304247651492"/>
			<inertia ixx="0.03" iyy="0.03" izz="0.03" ixy="0" ixz="0" iyx="0"/>
		</inertial>
	</link>
	<link name="576">
		<visual>
			<geometry>
				<sphere radius="0.546790288102742"/>
			</geometry>
		</visual>
		<collision>
			<geometry>
				<sphere radius="0.546790288102742"/>
			</geometry>
		</collision>
		<inertial>
			<mass value="1.0517241171501588"/>
			<inertia ixx="0.03" iyy="0.03" izz="0.03" ixy="0" ixz="0" iyx="0"/>
		</inertial>
	</link>
	<link name="577">
		<visual>
			<geometry>
				<sphere radius="0.546790288102742"/>
			</geometry>
		</visual>
		<collision>
			<geometry>
				<sphere radius="0.546790288102742"/>
			</geometry>
		</collision>
		<inertial>
			<mass value="1.0517241171501588"/>
			<inertia ixx="0.03" iyy="0.03" izz="0.03" ixy="0" ixz="0" iyx="0"/>
		</inertial>
	</link>
	<link name="578">
		<visual>
			<geometry>
				<sphere radius="0.546790288102742"/>
			</geometry>
		</visual>
		<collision>
			<geometry>
				<sphere radius="0.546790288102742"/>
			</geometry>
		</collision>
		<inertial>
			<mass value="1.0517241171501588"/>
			<inertia ixx="0.03" iyy="0.03" izz="0.03" ixy="0" ixz="0" iyx="0"/>
		</inertial>
	</link>
	<link name="479">
		<visual>
			<geometry>
				<sphere radius="0.05432080736827971"/>
			</geometry>
		</visual>
		<collision>
			<geometry>
				<sphere radius="0.05432080736827971"/>
			</geometry>
		</collision>
		<inertial>
			<mass value="0.015791304247651492"/>
			<inertia ixx="0.03" iyy="0.03" izz="0.03" ixy="0" ixz="0" iyx="0"/>
		</inertial>
	</link>
	<link name="580">
		<visual>
			<geometry>
				<sphere radius="0.546790288102742"/>
			</geometry>
		</visual>
		<collision>
			<geometry>
				<sphere radius="0.546790288102742"/>
			</geometry>
		</collision>
		<inertial>
			<mass value="1.0517241171501588"/>
			<inertia ixx="0.03" iyy="0.03" izz="0.03" ixy="0" ixz="0" iyx="0"/>
		</inertial>
	</link>
	<link name="581">
		<visual>
			<geometry>
				<sphere radius="0.546790288102742"/>
			</geometry>
		</visual>
		<collision>
			<geometry>
				<sphere radius="0.546790288102742"/>
			</geometry>
		</collision>
		<inertial>
			<mass value="1.0517241171501588"/>
			<inertia ixx="0.03" iyy="0.03" izz="0.03" ixy="0" ixz="0" iyx="0"/>
		</inertial>
	</link>
	<link name="582">
		<visual>
			<geometry>
				<sphere radius="0.546790288102742"/>
			</geometry>
		</visual>
		<collision>
			<geometry>
				<sphere radius="0.546790288102742"/>
			</geometry>
		</collision>
		<inertial>
			<mass value="1.0517241171501588"/>
			<inertia ixx="0.03" iyy="0.03" izz="0.03" ixy="0" ixz="0" iyx="0"/>
		</inertial>
	</link>
	<link name="483">
		<visual>
			<geometry>
				<sphere radius="0.05432080736827971"/>
			</geometry>
		</visual>
		<collision>
			<geometry>
				<sphere radius="0.05432080736827971"/>
			</geometry>
		</collision>
		<inertial>
			<mass value="0.015791304247651492"/>
			<inertia ixx="0.03" iyy="0.03" izz="0.03" ixy="0" ixz="0" iyx="0"/>
		</inertial>
	</link>
	<link name="584">
		<visual>
			<geometry>
				<sphere radius="0.546790288102742"/>
			</geometry>
		</visual>
		<collision>
			<geometry>
				<sphere radius="0.546790288102742"/>
			</geometry>
		</collision>
		<inertial>
			<mass value="1.0517241171501588"/>
			<inertia ixx="0.03" iyy="0.03" izz="0.03" ixy="0" ixz="0" iyx="0"/>
		</inertial>
	</link>
	<link name="585">
		<visual>
			<geometry>
				<sphere radius="0.546790288102742"/>
			</geometry>
		</visual>
		<collision>
			<geometry>
				<sphere radius="0.546790288102742"/>
			</geometry>
		</collision>
		<inertial>
			<mass value="1.0517241171501588"/>
			<inertia ixx="0.03" iyy="0.03" izz="0.03" ixy="0" ixz="0" iyx="0"/>
		</inertial>
	</link>
	<link name="586">
		<visual>
			<geometry>
				<sphere radius="0.546790288102742"/>
			</geometry>
		</visual>
		<collision>
			<geometry>
				<sphere radius="0.546790288102742"/>
			</geometry>
		</collision>
		<inertial>
			<mass value="1.0517241171501588"/>
			<inertia ixx="0.03" iyy="0.03" izz="0.03" ixy="0" ixz="0" iyx="0"/>
		</inertial>
	</link>
	<link name="187">
		<visual>
			<geometry>
				<sphere radius="0.5970695760447879"/>
			</geometry>
		</visual>
		<collision>
			<geometry>
				<sphere radius="0.5970695760447879"/>
			</geometry>
		</collision>
		<inertial>
			<mass value="0.8862245479835859"/>
			<inertia ixx="0.03" iyy="0.03" izz="0.03" ixy="0" ixz="0" iyx="0"/>
		</inertial>
	</link>
	<link name="288">
		<visual>
			<geometry>
				<sphere radius="0.914551099716554"/>
			</geometry>
		</visual>
		<collision>
			<geometry>
				<sphere radius="0.914551099716554"/>
			</geometry>
		</collision>
		<inertial>
			<mass value="2.3615934314283016"/>
			<inertia ixx="0.03" iyy="0.03" izz="0.03" ixy="0" ixz="0" iyx="0"/>
		</inertial>
	</link>
	<link name="389">
		<visual>
			<geometry>
				<sphere radius="0.41767174834899823"/>
			</geometry>
		</visual>
		<collision>
			<geometry>
				<sphere radius="0.41767174834899823"/>
			</geometry>
		</collision>
		<inertial>
			<mass value="0.9179345154310158"/>
			<inertia ixx="0.03" iyy="0.03" izz="0.03" ixy="0" ixz="0" iyx="0"/>
		</inertial>
	</link>
	<link name="490">
		<visual>
			<geometry>
				<sphere radius="0.05432080736827971"/>
			</geometry>
		</visual>
		<collision>
			<geometry>
				<sphere radius="0.05432080736827971"/>
			</geometry>
		</collision>
		<inertial>
			<mass value="0.015791304247651492"/>
			<inertia ixx="0.03" iyy="0.03" izz="0.03" ixy="0" ixz="0" iyx="0"/>
		</inertial>
	</link>
	<link name="591">
		<visual>
			<geometry>
				<sphere radius="0.546790288102742"/>
			</geometry>
		</visual>
		<collision>
			<geometry>
				<sphere radius="0.546790288102742"/>
			</geometry>
		</collision>
		<inertial>
			<mass value="1.0517241171501588"/>
			<inertia ixx="0.03" iyy="0.03" izz="0.03" ixy="0" ixz="0" iyx="0"/>
		</inertial>
	</link>
	<link name="592">
		<visual>
			<geometry>
				<sphere radius="0.546790288102742"/>
			</geometry>
		</visual>
		<collision>
			<geometry>
				<sphere radius="0.546790288102742"/>
			</geometry>
		</collision>
		<inertial>
			<mass value="1.0517241171501588"/>
			<inertia ixx="0.03" iyy="0.03" izz="0.03" ixy="0" ixz="0" iyx="0"/>
		</inertial>
	</link>
	<link name="593">
		<visual>
			<geometry>
				<sphere radius="0.546790288102742"/>
			</geometry>
		</visual>
		<collision>
			<geometry>
				<sphere radius="0.546790288102742"/>
			</geometry>
		</collision>
		<inertial>
			<mass value="1.0517241171501588"/>
			<inertia ixx="0.03" iyy="0.03" izz="0.03" ixy="0" ixz="0" iyx="0"/>
		</inertial>
	</link>
	<link name="494">
		<visual>
			<geometry>
				<sphere radius="0.05432080736827971"/>
			</geometry>
		</visual>
		<collision>
			<geometry>
				<sphere radius="0.05432080736827971"/>
			</geometry>
		</collision>
		<inertial>
			<mass value="0.015791304247651492"/>
			<inertia ixx="0.03" iyy="0.03" izz="0.03" ixy="0" ixz="0" iyx="0"/>
		</inertial>
	</link>
	<link name="595">
		<visual>
			<geometry>
				<sphere radius="0.546790288102742"/>
			</geometry>
		</visual>
		<collision>
			<geometry>
				<sphere radius="0.546790288102742"/>
			</geometry>
		</collision>
		<inertial>
			<mass value="1.0517241171501588"/>
			<inertia ixx="0.03" iyy="0.03" izz="0.03" ixy="0" ixz="0" iyx="0"/>
		</inertial>
	</link>
	<link name="596">
		<visual>
			<geometry>
				<sphere radius="0.546790288102742"/>
			</geometry>
		</visual>
		<collision>
			<geometry>
				<sphere radius="0.546790288102742"/>
			</geometry>
		</collision>
		<inertial>
			<mass value="1.0517241171501588"/>
			<inertia ixx="0.03" iyy="0.03" izz="0.03" ixy="0" ixz="0" iyx="0"/>
		</inertial>
	</link>
	<link name="597">
		<visual>
			<geometry>
				<sphere radius="0.546790288102742"/>
			</geometry>
		</visual>
		<collision>
			<geometry>
				<sphere radius="0.546790288102742"/>
			</geometry>
		</collision>
		<inertial>
			<mass value="1.0517241171501588"/>
			<inertia ixx="0.03" iyy="0.03" izz="0.03" ixy="0" ixz="0" iyx="0"/>
		</inertial>
	</link>
	<link name="498">
		<visual>
			<geometry>
				<sphere radius="0.05432080736827971"/>
			</geometry>
		</visual>
		<collision>
			<geometry>
				<sphere radius="0.05432080736827971"/>
			</geometry>
		</collision>
		<inertial>
			<mass value="0.015791304247651492"/>
			<inertia ixx="0.03" iyy="0.03" izz="0.03" ixy="0" ixz="0" iyx="0"/>
		</inertial>
	</link>
	<link name="599">
		<visual>
			<geometry>
				<sphere radius="0.546790288102742"/>
			</geometry>
		</visual>
		<collision>
			<geometry>
				<sphere radius="0.546790288102742"/>
			</geometry>
		</collision>
		<inertial>
			<mass value="1.0517241171501588"/>
			<inertia ixx="0.03" iyy="0.03" izz="0.03" ixy="0" ixz="0" iyx="0"/>
		</inertial>
	</link>
	<link name="5100">
		<visual>
			<geometry>
				<sphere radius="0.546790288102742"/>
			</geometry>
		</visual>
		<collision>
			<geometry>
				<sphere radius="0.546790288102742"/>
			</geometry>
		</collision>
		<inertial>
			<mass value="1.0517241171501588"/>
			<inertia ixx="0.03" iyy="0.03" izz="0.03" ixy="0" ixz="0" iyx="0"/>
		</inertial>
	</link>
	<link name="5101">
		<visual>
			<geometry>
				<sphere radius="0.546790288102742"/>
			</geometry>
		</visual>
		<collision>
			<geometry>
				<sphere radius="0.546790288102742"/>
			</geometry>
		</collision>
		<inertial>
			<mass value="1.0517241171501588"/>
			<inertia ixx="0.03" iyy="0.03" izz="0.03" ixy="0" ixz="0" iyx="0"/>
		</inertial>
	</link>
	<link name="2102">
		<visual>
			<geometry>
				<sphere radius="0.914551099716554"/>
			</geometry>
		</visual>
		<collision>
			<geometry>
				<sphere radius="0.914551099716554"/>
			</geometry>
		</collision>
		<inertial>
			<mass value="2.3615934314283016"/>
			<inertia ixx="0.03" iyy="0.03" izz="0.03" ixy="0" ixz="0" iyx="0"/>
		</inertial>
	</link>
	<link name="3103">
		<visual>
			<geometry>
				<sphere radius="0.41767174834899823"/>
			</geometry>
		</visual>
		<collision>
			<geometry>
				<sphere radius="0.41767174834899823"/>
			</geometry>
		</collision>
		<inertial>
			<mass value="0.9179345154310158"/>
			<inertia ixx="0.03" iyy="0.03" izz="0.03" ixy="0" ixz="0" iyx="0"/>
		</inertial>
	</link>
	<link name="4104">
		<visual>
			<geometry>
				<sphere radius="0.05432080736827971"/>
			</geometry>
		</visual>
		<collision>
			<geometry>
				<sphere radius="0.05432080736827971"/>
			</geometry>
		</collision>
		<inertial>
			<mass value="0.015791304247651492"/>
			<inertia ixx="0.03" iyy="0.03" izz="0.03" ixy="0" ixz="0" iyx="0"/>
		</inertial>
	</link>
	<link name="5105">
		<visual>
			<geometry>
				<sphere radius="0.546790288102742"/>
			</geometry>
		</visual>
		<collision>
			<geometry>
				<sphere radius="0.546790288102742"/>
			</geometry>
		</collision>
		<inertial>
			<mass value="1.0517241171501588"/>
			<inertia ixx="0.03" iyy="0.03" izz="0.03" ixy="0" ixz="0" iyx="0"/>
		</inertial>
	</link>
	<link name="5106">
		<visual>
			<geometry>
				<sphere radius="0.546790288102742"/>
			</geometry>
		</visual>
		<collision>
			<geometry>
				<sphere radius="0.546790288102742"/>
			</geometry>
		</collision>
		<inertial>
			<mass value="1.0517241171501588"/>
			<inertia ixx="0.03" iyy="0.03" izz="0.03" ixy="0" ixz="0" iyx="0"/>
		</inertial>
	</link>
	<link name="5107">
		<visual>
			<geometry>
				<sphere radius="0.546790288102742"/>
			</geometry>
		</visual>
		<collision>
			<geometry>
				<sphere radius="0.546790288102742"/>
			</geometry>
		</collision>
		<inertial>
			<mass value="1.0517241171501588"/>
			<inertia ixx="0.03" iyy="0.03" izz="0.03" ixy="0" ixz="0" iyx="0"/>
		</inertial>
	</link>
	<link name="4108">
		<visual>
			<geometry>
				<sphere radius="0.05432080736827971"/>
			</geometry>
		</visual>
		<collision>
			<geometry>
				<sphere radius="0.05432080736827971"/>
			</geometry>
		</collision>
		<inertial>
			<mass value="0.015791304247651492"/>
			<inertia ixx="0.03" iyy="0.03" izz="0.03" ixy="0" ixz="0" iyx="0"/>
		</inertial>
	</link>
	<link name="5109">
		<visual>
			<geometry>
				<sphere radius="0.546790288102742"/>
			</geometry>
		</visual>
		<collision>
			<geometry>
				<sphere radius="0.546790288102742"/>
			</geometry>
		</collision>
		<inertial>
			<mass value="1.0517241171501588"/>
			<inertia ixx="0.03" iyy="0.03" izz="0.03" ixy="0" ixz="0" iyx="0"/>
		</inertial>
	</link>
	<link name="5110">
		<visual>
			<geometry>
				<sphere radius="0.546790288102742"/>
			</geometry>
		</visual>
		<collision>
			<geometry>
				<sphere radius="0.546790288102742"/>
			</geometry>
		</collision>
		<inertial>
			<mass value="1.0517241171501588"/>
			<inertia ixx="0.03" iyy="0.03" izz="0.03" ixy="0" ixz="0" iyx="0"/>
		</inertial>
	</link>
	<link name="5111">
		<visual>
			<geometry>
				<sphere radius="0.546790288102742"/>
			</geometry>
		</visual>
		<collision>
			<geometry>
				<sphere radius="0.546790288102742"/>
			</geometry>
		</collision>
		<inertial>
			<mass value="1.0517241171501588"/>
			<inertia ixx="0.03" iyy="0.03" izz="0.03" ixy="0" ixz="0" iyx="0"/>
		</inertial>
	</link>
	<link name="4112">
		<visual>
			<geometry>
				<sphere radius="0.05432080736827971"/>
			</geometry>
		</visual>
		<collision>
			<geometry>
				<sphere radius="0.05432080736827971"/>
			</geometry>
		</collision>
		<inertial>
			<mass value="0.015791304247651492"/>
			<inertia ixx="0.03" iyy="0.03" izz="0.03" ixy="0" ixz="0" iyx="0"/>
		</inertial>
	</link>
	<link name="5113">
		<visual>
			<geometry>
				<sphere radius="0.546790288102742"/>
			</geometry>
		</visual>
		<collision>
			<geometry>
				<sphere radius="0.546790288102742"/>
			</geometry>
		</collision>
		<inertial>
			<mass value="1.0517241171501588"/>
			<inertia ixx="0.03" iyy="0.03" izz="0.03" ixy="0" ixz="0" iyx="0"/>
		</inertial>
	</link>
	<link name="5114">
		<visual>
			<geometry>
				<sphere radius="0.546790288102742"/>
			</geometry>
		</visual>
		<collision>
			<geometry>
				<sphere radius="0.546790288102742"/>
			</geometry>
		</collision>
		<inertial>
			<mass value="1.0517241171501588"/>
			<inertia ixx="0.03" iyy="0.03" izz="0.03" ixy="0" ixz="0" iyx="0"/>
		</inertial>
	</link>
	<link name="5115">
		<visual>
			<geometry>
				<sphere radius="0.546790288102742"/>
			</geometry>
		</visual>
		<collision>
			<geometry>
				<sphere radius="0.546790288102742"/>
			</geometry>
		</collision>
		<inertial>
			<mass value="1.0517241171501588"/>
			<inertia ixx="0.03" iyy="0.03" izz="0.03" ixy="0" ixz="0" iyx="0"/>
		</inertial>
	</link>
	<link name="2116">
		<visual>
			<geometry>
				<sphere radius="0.914551099716554"/>
			</geometry>
		</visual>
		<collision>
			<geometry>
				<sphere radius="0.914551099716554"/>
			</geometry>
		</collision>
		<inertial>
			<mass value="2.3615934314283016"/>
			<inertia ixx="0.03" iyy="0.03" izz="0.03" ixy="0" ixz="0" iyx="0"/>
		</inertial>
	</link>
	<link name="3117">
		<visual>
			<geometry>
				<sphere radius="0.41767174834899823"/>
			</geometry>
		</visual>
		<collision>
			<geometry>
				<sphere radius="0.41767174834899823"/>
			</geometry>
		</collision>
		<inertial>
			<mass value="0.9179345154310158"/>
			<inertia ixx="0.03" iyy="0.03" izz="0.03" ixy="0" ixz="0" iyx="0"/>
		</inertial>
	</link>
	<link name="4118">
		<visual>
			<geometry>
				<sphere radius="0.05432080736827971"/>
			</geometry>
		</visual>
		<collision>
			<geometry>
				<sphere radius="0.05432080736827971"/>
			</geometry>
		</collision>
		<inertial>
			<mass value="0.015791304247651492"/>
			<inertia ixx="0.03" iyy="0.03" izz="0.03" ixy="0" ixz="0" iyx="0"/>
		</inertial>
	</link>
	<link name="5119">
		<visual>
			<geometry>
				<sphere radius="0.546790288102742"/>
			</geometry>
		</visual>
		<collision>
			<geometry>
				<sphere radius="0.546790288102742"/>
			</geometry>
		</collision>
		<inertial>
			<mass value="1.0517241171501588"/>
			<inertia ixx="0.03" iyy="0.03" izz="0.03" ixy="0" ixz="0" iyx="0"/>
		</inertial>
	</link>
	<link name="5120">
		<visual>
			<geometry>
				<sphere radius="0.546790288102742"/>
			</geometry>
		</visual>
		<collision>
			<geometry>
				<sphere radius="0.546790288102742"/>
			</geometry>
		</collision>
		<inertial>
			<mass value="1.0517241171501588"/>
			<inertia ixx="0.03" iyy="0.03" izz="0.03" ixy="0" ixz="0" iyx="0"/>
		</inertial>
	</link>
	<link name="5121">
		<visual>
			<geometry>
				<sphere radius="0.546790288102742"/>
			</geometry>
		</visual>
		<collision>
			<geometry>
				<sphere radius="0.546790288102742"/>
			</geometry>
		</collision>
		<inertial>
			<mass value="1.0517241171501588"/>
			<inertia ixx="0.03" iyy="0.03" izz="0.03" ixy="0" ixz="0" iyx="0"/>
		</inertial>
	</link>
	<link name="4122">
		<visual>
			<geometry>
				<sphere radius="0.05432080736827971"/>
			</geometry>
		</visual>
		<collision>
			<geometry>
				<sphere radius="0.05432080736827971"/>
			</geometry>
		</collision>
		<inertial>
			<mass value="0.015791304247651492"/>
			<inertia ixx="0.03" iyy="0.03" izz="0.03" ixy="0" ixz="0" iyx="0"/>
		</inertial>
	</link>
	<link name="5123">
		<visual>
			<geometry>
				<sphere radius="0.546790288102742"/>
			</geometry>
		</visual>
		<collision>
			<geometry>
				<sphere radius="0.546790288102742"/>
			</geometry>
		</collision>
		<inertial>
			<mass value="1.0517241171501588"/>
			<inertia ixx="0.03" iyy="0.03" izz="0.03" ixy="0" ixz="0" iyx="0"/>
		</inertial>
	</link>
	<link name="5124">
		<visual>
			<geometry>
				<sphere radius="0.546790288102742"/>
			</geometry>
		</visual>
		<collision>
			<geometry>
				<sphere radius="0.546790288102742"/>
			</geometry>
		</collision>
		<inertial>
			<mass value="1.0517241171501588"/>
			<inertia ixx="0.03" iyy="0.03" izz="0.03" ixy="0" ixz="0" iyx="0"/>
		</inertial>
	</link>
	<link name="5125">
		<visual>
			<geometry>
				<sphere radius="0.546790288102742"/>
			</geometry>
		</visual>
		<collision>
			<geometry>
				<sphere radius="0.546790288102742"/>
			</geometry>
		</collision>
		<inertial>
			<mass value="1.0517241171501588"/>
			<inertia ixx="0.03" iyy="0.03" izz="0.03" ixy="0" ixz="0" iyx="0"/>
		</inertial>
	</link>
	<link name="4126">
		<visual>
			<geometry>
				<sphere radius="0.05432080736827971"/>
			</geometry>
		</visual>
		<collision>
			<geometry>
				<sphere radius="0.05432080736827971"/>
			</geometry>
		</collision>
		<inertial>
			<mass value="0.015791304247651492"/>
			<inertia ixx="0.03" iyy="0.03" izz="0.03" ixy="0" ixz="0" iyx="0"/>
		</inertial>
	</link>
	<link name="5127">
		<visual>
			<geometry>
				<sphere radius="0.546790288102742"/>
			</geometry>
		</visual>
		<collision>
			<geometry>
				<sphere radius="0.546790288102742"/>
			</geometry>
		</collision>
		<inertial>
			<mass value="1.0517241171501588"/>
			<inertia ixx="0.03" iyy="0.03" izz="0.03" ixy="0" ixz="0" iyx="0"/>
		</inertial>
	</link>
	<link name="5128">
		<visual>
			<geometry>
				<sphere radius="0.546790288102742"/>
			</geometry>
		</visual>
		<collision>
			<geometry>
				<sphere radius="0.546790288102742"/>
			</geometry>
		</collision>
		<inertial>
			<mass value="1.0517241171501588"/>
			<inertia ixx="0.03" iyy="0.03" izz="0.03" ixy="0" ixz="0" iyx="0"/>
		</inertial>
	</link>
	<link name="5129">
		<visual>
			<geometry>
				<sphere radius="0.546790288102742"/>
			</geometry>
		</visual>
		<collision>
			<geometry>
				<sphere radius="0.546790288102742"/>
			</geometry>
		</collision>
		<inertial>
			<mass value="1.0517241171501588"/>
			<inertia ixx="0.03" iyy="0.03" izz="0.03" ixy="0" ixz="0" iyx="0"/>
		</inertial>
	</link>
	<joint name="11_to_0" type="revolute">
		<parent link="0"/>
		<child link="11"/>
		<axis xyz="0 1 0"/>
		<limit effort="1" upper="-3.1415" lower="3.1415" velocity="1"/>
		<origin rpy="12.35483736540991 6.150867155797274 5.514166033265675" xyz="0.005096555782734602 0.11978472283039487 0.28889542575000915"/>
	</joint>
	<joint name="22_to_11" type="revolute">
		<parent link="11"/>
		<child link="22"/>
		<axis xyz="0 1 0"/>
		<limit effort="1" upper="-3.1415" lower="3.1415" velocity="1"/>
		<origin rpy="11.477647711201918 2.9386225977356184 3.6706140324167555" xyz="0.34604144637492684 0.9486809796451484 0.6204757887286447"/>
	</joint>
	<joint name="33_to_22" type="revolute">
		<parent link="22"/>
		<child link="33"/>
		<axis xyz="0 1 0"/>
		<limit effort="1" upper="-3.1415" lower="3.1415" velocity="1"/>
		<origin rpy="9.964080971456038 2.2778805616572106 2.9818501228947247" xyz="0.937859089294457 0.302460945118709 0.42483515932786386"/>
	</joint>
	<joint name="44_to_22" type="revolute">
		<parent link="22"/>
		<child link="44"/>
		<axis xyz="1 0 0"/>
		<limit effort="1" upper="-3.1415" lower="3.1415" velocity="1"/>
		<origin rpy="0.7261506588443705 3.63012818266156 1.5900322297015883" xyz="0.6584528667977734 0.10496627348971621 0.19411505082504898"/>
	</joint>
	<joint name="55_to_44" type="revolute">
		<parent link="44"/>
		<child link="55"/>
		<axis xyz="1 0 0"/>
		<limit effort="1" upper="-3.1415" lower="3.1415" velocity="1"/>
		<origin rpy="5.866418402424061 5.048527159697937 3.393981427221651" xyz="0.5127213343181469 0.10629285425074997 0.63826820322367"/>
	</joint>
	<joint name="56_to_44" type="revolute">
		<parent link="44"/>
		<child link="56"/>
		<axis xyz="1 0 0"/>
		<limit effort="1" upper="-3.1415" lower="3.1415" velocity="1"/>
		<origin rpy="8.799627603636091 5.048527159697937 3.393981427221651" xyz="0.5127213343181469 0.10629285425074997 0.63826820322367"/>
	</joint>
	<joint name="57_to_44" type="revolute">
		<parent link="44"/>
		<child link="57"/>
		<axis xyz="1 0 0"/>
		<limit effort="1" upper="-3.1415" lower="3.1415" velocity="1"/>
		<origin rpy="11.732836804848121 5.048527159697937 3.393981427221651" xyz="0.5127213343181469 0.10629285425074997 0.63826820322367"/>
	</joint>
	<joint name="48_to_22" type="revolute">
		<parent link="22"/>
		<child link="48"/>
		<axis xyz="1 0 0"/>
		<limit effort="1" upper="-3.1415" lower="3.1415" velocity="1"/>
		<origin rpy="0.9682008784591607 3.63012818266156 1.5900322297015883" xyz="0.6584528667977734 0.10496627348971621 0.19411505082504898"/>
	</joint>
	<joint name="59_to_48" type="revolute">
		<parent link="48"/>
		<child link="59"/>
		<axis xyz="1 0 0"/>
		<limit effort="1" upper="-3.1415" lower="3.1415" velocity="1"/>
		<origin rpy="5.866418402424061 5.048527159697937 3.393981427221651" xyz="0.5127213343181469 0.10629285425074997 0.63826820322367"/>
	</joint>
	<joint name="510_to_48" type="revolute">
		<parent link="48"/>
		<child link="510"/>
		<axis xyz="1 0 0"/>
		<limit effort="1" upper="-3.1415" lower="3.1415" velocity="1"/>
		<origin rpy="8.799627603636091 5.048527159697937 3.393981427221651" xyz="0.5127213343181469 0.10629285425074997 0.63826820322367"/>
	</joint>
	<joint name="511_to_48" type="revolute">
		<parent link="48"/>
		<child link="511"/>
		<axis xyz="1 0 0"/>
		<limit effort="1" upper="-3.1415" lower="3.1415" velocity="1"/>
		<origin rpy="11.732836804848121 5.048527159697937 3.393981427221651" xyz="0.5127213343181469 0.10629285425074997 0.63826820322367"/>
	</joint>
	<joint name="412_to_22" type="revolute">
		<parent link="22"/>
		<child link="412"/>
		<axis xyz="1 0 0"/>
		<limit effort="1" upper="-3.1415" lower="3.1415" velocity="1"/>
		<origin rpy="1.210251098073951 3.63012818266156 1.5900322297015883" xyz="0.6584528667977734 0.10496627348971621 0.19411505082504898"/>
	</joint>
	<joint name="513_to_412" type="revolute">
		<parent link="412"/>
		<child link="513"/>
		<axis xyz="1 0 0"/>
		<limit effort="1" upper="-3.1415" lower="3.1415" velocity="1"/>
		<origin rpy="5.866418402424061 5.048527159697937 3.393981427221651" xyz="0.5127213343181469 0.10629285425074997 0.63826820322367"/>
	</joint>
	<joint name="514_to_412" type="revolute">
		<parent link="412"/>
		<child link="514"/>
		<axis xyz="1 0 0"/>
		<limit effort="1" upper="-3.1415" lower="3.1415" velocity="1"/>
		<origin rpy="8.799627603636091 5.048527159697937 3.393981427221651" xyz="0.5127213343181469 0.10629285425074997 0.63826820322367"/>
	</joint>
	<joint name="515_to_412" type="revolute">
		<parent link="412"/>
		<child link="515"/>
		<axis xyz="1 0 0"/>
		<limit effort="1" upper="-3.1415" lower="3.1415" velocity="1"/>
		<origin rpy="11.732836804848121 5.048527159697937 3.393981427221651" xyz="0.5127213343181469 0.10629285425074997 0.63826820322367"/>
	</joint>
	<joint name="216_to_11" type="revolute">
		<parent link="11"/>
		<child link="216"/>
		<axis xyz="0 1 0"/>
		<limit effort="1" upper="-3.1415" lower="3.1415" velocity="1"/>
		<origin rpy="17.216471566802877 2.9386225977356184 3.6706140324167555" xyz="0.34604144637492684 0.9486809796451484 0.6204757887286447"/>
	</joint>
	<joint name="317_to_216" type="revolute">
		<parent link="216"/>
		<child link="317"/>
		<axis xyz="0 1 0"/>
		<limit effort="1" upper="-3.1415" lower="3.1415" velocity="1"/>
		<origin rpy="9.964080971456038 2.2778805616572106 2.9818501228947247" xyz="0.937859089294457 0.302460945118709 0.42483515932786386"/>
	</joint>
	<joint name="418_to_216" type="revolute">
		<parent link="216"/>
		<child link="418"/>
		<axis xyz="1 0 0"/>
		<limit effort="1" upper="-3.1415" lower="3.1415" velocity="1"/>
		<origin rpy="0.7261506588443705 3.63012818266156 1.5900322297015883" xyz="0.6584528667977734 0.10496627348971621 0.19411505082504898"/>
	</joint>
	<joint name="519_to_418" type="revolute">
		<parent link="418"/>
		<child link="519"/>
		<axis xyz="1 0 0"/>
		<limit effort="1" upper="-3.1415" lower="3.1415" velocity="1"/>
		<origin rpy="5.866418402424061 5.048527159697937 3.393981427221651" xyz="0.5127213343181469 0.10629285425074997 0.63826820322367"/>
	</joint>
	<joint name="520_to_418" type="revolute">
		<parent link="418"/>
		<child link="520"/>
		<axis xyz="1 0 0"/>
		<limit effort="1" upper="-3.1415" lower="3.1415" velocity="1"/>
		<origin rpy="8.799627603636091 5.048527159697937 3.393981427221651" xyz="0.5127213343181469 0.10629285425074997 0.63826820322367"/>
	</joint>
	<joint name="521_to_418" type="revolute">
		<parent link="418"/>
		<child link="521"/>
		<axis xyz="1 0 0"/>
		<limit effort="1" upper="-3.1415" lower="3.1415" velocity="1"/>
		<origin rpy="11.732836804848121 5.048527159697937 3.393981427221651" xyz="0.5127213343181469 0.10629285425074997 0.63826820322367"/>
	</joint>
	<joint name="422_to_216" type="revolute">
		<parent link="216"/>
		<child link="422"/>
		<axis xyz="1 0 0"/>
		<limit effort="1" upper="-3.1415" lower="3.1415" velocity="1"/>
		<origin rpy="0.9682008784591607 3.63012818266156 1.5900322297015883" xyz="0.6584528667977734 0.10496627348971621 0.19411505082504898"/>
	</joint>
	<joint name="523_to_422" type="revolute">
		<parent link="422"/>
		<child link="523"/>
		<axis xyz="1 0 0"/>
		<limit effort="1" upper="-3.1415" lower="3.1415" velocity="1"/>
		<origin rpy="5.866418402424061 5.048527159697937 3.393981427221651" xyz="0.5127213343181469 0.10629285425074997 0.63826820322367"/>
	</joint>
	<joint name="524_to_422" type="revolute">
		<parent link="422"/>
		<child link="524"/>
		<axis xyz="1 0 0"/>
		<limit effort="1" upper="-3.1415" lower="3.1415" velocity="1"/>
		<origin rpy="8.799627603636091 5.048527159697937 3.393981427221651" xyz="0.5127213343181469 0.10629285425074997 0.63826820322367"/>
	</joint>
	<joint name="525_to_422" type="revolute">
		<parent link="422"/>
		<child link="525"/>
		<axis xyz="1 0 0"/>
		<limit effort="1" upper="-3.1415" lower="3.1415" velocity="1"/>
		<origin rpy="11.732836804848121 5.048527159697937 3.393981427221651" xyz="0.5127213343181469 0.10629285425074997 0.63826820322367"/>
	</joint>
	<joint name="426_to_216" type="revolute">
		<parent link="216"/>
		<child link="426"/>
		<axis xyz="1 0 0"/>
		<limit effort="1" upper="-3.1415" lower="3.1415" velocity="1"/>
		<origin rpy="1.210251098073951 3.63012818266156 1.5900322297015883" xyz="0.6584528667977734 0.10496627348971621 0.19411505082504898"/>
	</joint>
	<joint name="527_to_426" type="revolute">
		<parent link="426"/>
		<child link="527"/>
		<axis xyz="1 0 0"/>
		<limit effort="1" upper="-3.1415" lower="3.1415" velocity="1"/>
		<origin rpy="5.866418402424061 5.048527159697937 3.393981427221651" xyz="0.5127213343181469 0.10629285425074997 0.63826820322367"/>
	</joint>
	<joint name="528_to_426" type="revolute">
		<parent link="426"/>
		<child link="528"/>
		<axis xyz="1 0 0"/>
		<limit effort="1" upper="-3.1415" lower="3.1415" velocity="1"/>
		<origin rpy="8.799627603636091 5.048527159697937 3.393981427221651" xyz="0.5127213343181469 0.10629285425074997 0.63826820322367"/>
	</joint>
	<joint name="529_to_426" type="revolute">
		<parent link="426"/>
		<child link="529"/>
		<axis xyz="1 0 0"/>
		<limit effort="1" upper="-3.1415" lower="3.1415" velocity="1"/>
		<origin rpy="11.732836804848121 5.048527159697937 3.393981427221651" xyz="0.5127213343181469 0.10629285425074997 0.63826820322367"/>
	</joint>
	<joint name="230_to_11" type="revolute">
		<parent link="11"/>
		<child link="230"/>
		<axis xyz="0 1 0"/>
		<limit effort="1" upper="-3.1415" lower="3.1415" velocity="1"/>
		<origin rpy="22.955295422403836 2.9386225977356184 3.6706140324167555" xyz="0.34604144637492684 0.9486809796451484 0.6204757887286447"/>
	</joint>
	<joint name="331_to_230" type="revolute">
		<parent link="230"/>
		<child link="331"/>
		<axis xyz="0 1 0"/>
		<limit effort="1" upper="-3.1415" lower="3.1415" velocity="1"/>
		<origin rpy="9.964080971456038 2.2778805616572106 2.9818501228947247" xyz="0.937859089294457 0.302460945118709 0.42483515932786386"/>
	</joint>
	<joint name="432_to_230" type="revolute">
		<parent link="230"/>
		<child link="432"/>
		<axis xyz="1 0 0"/>
		<limit effort="1" upper="-3.1415" lower="3.1415" velocity="1"/>
		<origin rpy="0.7261506588443705 3.63012818266156 1.5900322297015883" xyz="0.6584528667977734 0.10496627348971621 0.19411505082504898"/>
	</joint>
	<joint name="533_to_432" type="revolute">
		<parent link="432"/>
		<child link="533"/>
		<axis xyz="1 0 0"/>
		<limit effort="1" upper="-3.1415" lower="3.1415" velocity="1"/>
		<origin rpy="5.866418402424061 5.048527159697937 3.393981427221651" xyz="0.5127213343181469 0.10629285425074997 0.63826820322367"/>
	</joint>
	<joint name="534_to_432" type="revolute">
		<parent link="432"/>
		<child link="534"/>
		<axis xyz="1 0 0"/>
		<limit effort="1" upper="-3.1415" lower="3.1415" velocity="1"/>
		<origin rpy="8.799627603636091 5.048527159697937 3.393981427221651" xyz="0.5127213343181469 0.10629285425074997 0.63826820322367"/>
	</joint>
	<joint name="535_to_432" type="revolute">
		<parent link="432"/>
		<child link="535"/>
		<axis xyz="1 0 0"/>
		<limit effort="1" upper="-3.1415" lower="3.1415" velocity="1"/>
		<origin rpy="11.732836804848121 5.048527159697937 3.393981427221651" xyz="0.5127213343181469 0.10629285425074997 0.63826820322367"/>
	</joint>
	<joint name="436_to_230" type="revolute">
		<parent link="230"/>
		<child link="436"/>
		<axis xyz="1 0 0"/>
		<limit effort="1" upper="-3.1415" lower="3.1415" velocity="1"/>
		<origin rpy="0.9682008784591607 3.63012818266156 1.5900322297015883" xyz="0.6584528667977734 0.10496627348971621 0.19411505082504898"/>
	</joint>
	<joint name="537_to_436" type="revolute">
		<parent link="436"/>
		<child link="537"/>
		<axis xyz="1 0 0"/>
		<limit effort="1" upper="-3.1415" lower="3.1415" velocity="1"/>
		<origin rpy="5.866418402424061 5.048527159697937 3.393981427221651" xyz="0.5127213343181469 0.10629285425074997 0.63826820322367"/>
	</joint>
	<joint name="538_to_436" type="revolute">
		<parent link="436"/>
		<child link="538"/>
		<axis xyz="1 0 0"/>
		<limit effort="1" upper="-3.1415" lower="3.1415" velocity="1"/>
		<origin rpy="8.799627603636091 5.048527159697937 3.393981427221651" xyz="0.5127213343181469 0.10629285425074997 0.63826820322367"/>
	</joint>
	<joint name="539_to_436" type="revolute">
		<parent link="436"/>
		<child link="539"/>
		<axis xyz="1 0 0"/>
		<limit effort="1" upper="-3.1415" lower="3.1415" velocity="1"/>
		<origin rpy="11.732836804848121 5.048527159697937 3.393981427221651" xyz="0.5127213343181469 0.10629285425074997 0.63826820322367"/>
	</joint>
	<joint name="440_to_230" type="revolute">
		<parent link="230"/>
		<child link="440"/>
		<axis xyz="1 0 0"/>
		<limit effort="1" upper="-3.1415" lower="3.1415" velocity="1"/>
		<origin rpy="1.210251098073951 3.63012818266156 1.5900322297015883" xyz="0.6584528667977734 0.10496627348971621 0.19411505082504898"/>
	</joint>
	<joint name="541_to_440" type="revolute">
		<parent link="440"/>
		<child link="541"/>
		<axis xyz="1 0 0"/>
		<limit effort="1" upper="-3.1415" lower="3.1415" velocity="1"/>
		<origin rpy="5.866418402424061 5.048527159697937 3.393981427221651" xyz="0.5127213343181469 0.10629285425074997 0.63826820322367"/>
	</joint>
	<joint name="542_to_440" type="revolute">
		<parent link="440"/>
		<child link="542"/>
		<axis xyz="1 0 0"/>
		<limit effort="1" upper="-3.1415" lower="3.1415" velocity="1"/>
		<origin rpy="8.799627603636091 5.048527159697937 3.393981427221651" xyz="0.5127213343181469 0.10629285425074997 0.63826820322367"/>
	</joint>
	<joint name="543_to_440" type="revolute">
		<parent link="440"/>
		<child link="543"/>
		<axis xyz="1 0 0"/>
		<limit effort="1" upper="-3.1415" lower="3.1415" velocity="1"/>
		<origin rpy="11.732836804848121 5.048527159697937 3.393981427221651" xyz="0.5127213343181469 0.10629285425074997 0.63826820322367"/>
	</joint>
	<joint name="144_to_0" type="revolute">
		<parent link="0"/>
		<child link="144"/>
		<axis xyz="0 1 0"/>
		<limit effort="1" upper="-3.1415" lower="3.1415" velocity="1"/>
		<origin rpy="18.532256048114867 6.150867155797274 5.514166033265675" xyz="0.005096555782734602 0.11978472283039487 0.28889542575000915"/>
	</joint>
	<joint name="245_to_144" type="revolute">
		<parent link="144"/>
		<child link="245"/>
		<axis xyz="0 1 0"/>
		<limit effort="1" upper="-3.1415" lower="3.1415" velocity="1"/>
		<origin rpy="11.477647711201918 2.9386225977356184 3.6706140324167555" xyz="0.34604144637492684 0.9486809796451484 0.6204757887286447"/>
	</joint>
	<joint name="346_to_245" type="revolute">
		<parent link="245"/>
		<child link="346"/>
		<axis xyz="0 1 0"/>
		<limit effort="1" upper="-3.1415" lower="3.1415" velocity="1"/>
		<origin rpy="9.964080971456038 2.2778805616572106 2.9818501228947247" xyz="0.937859089294457 0.302460945118709 0.42483515932786386"/>
	</joint>
	<joint name="447_to_245" type="revolute">
		<parent link="245"/>
		<child link="447"/>
		<axis xyz="1 0 0"/>
		<limit effort="1" upper="-3.1415" lower="3.1415" velocity="1"/>
		<origin rpy="0.7261506588443705 3.63012818266156 1.5900322297015883" xyz="0.6584528667977734 0.10496627348971621 0.19411505082504898"/>
	</joint>
	<joint name="548_to_447" type="revolute">
		<parent link="447"/>
		<child link="548"/>
		<axis xyz="1 0 0"/>
		<limit effort="1" upper="-3.1415" lower="3.1415" velocity="1"/>
		<origin rpy="5.866418402424061 5.048527159697937 3.393981427221651" xyz="0.5127213343181469 0.10629285425074997 0.63826820322367"/>
	</joint>
	<joint name="549_to_447" type="revolute">
		<parent link="447"/>
		<child link="549"/>
		<axis xyz="1 0 0"/>
		<limit effort="1" upper="-3.1415" lower="3.1415" velocity="1"/>
		<origin rpy="8.799627603636091 5.048527159697937 3.393981427221651" xyz="0.5127213343181469 0.10629285425074997 0.63826820322367"/>
	</joint>
	<joint name="550_to_447" type="revolute">
		<parent link="447"/>
		<child link="550"/>
		<axis xyz="1 0 0"/>
		<limit effort="1" upper="-3.1415" lower="3.1415" velocity="1"/>
		<origin rpy="11.732836804848121 5.048527159697937 3.393981427221651" xyz="0.5127213343181469 0.10629285425074997 0.63826820322367"/>
	</joint>
	<joint name="451_to_245" type="revolute">
		<parent link="245"/>
		<child link="451"/>
		<axis xyz="1 0 0"/>
		<limit effort="1" upper="-3.1415" lower="3.1415" velocity="1"/>
		<origin rpy="0.9682008784591607 3.63012818266156 1.5900322297015883" xyz="0.6584528667977734 0.10496627348971621 0.19411505082504898"/>
	</joint>
	<joint name="552_to_451" type="revolute">
		<parent link="451"/>
		<child link="552"/>
		<axis xyz="1 0 0"/>
		<limit effort="1" upper="-3.1415" lower="3.1415" velocity="1"/>
		<origin rpy="5.866418402424061 5.048527159697937 3.393981427221651" xyz="0.5127213343181469 0.10629285425074997 0.63826820322367"/>
	</joint>
	<joint name="553_to_451" type="revolute">
		<parent link="451"/>
		<child link="553"/>
		<axis xyz="1 0 0"/>
		<limit effort="1" upper="-3.1415" lower="3.1415" velocity="1"/>
		<origin rpy="8.799627603636091 5.048527159697937 3.393981427221651" xyz="0.5127213343181469 0.10629285425074997 0.63826820322367"/>
	</joint>
	<joint name="554_to_451" type="revolute">
		<parent link="451"/>
		<child link="554"/>
		<axis xyz="1 0 0"/>
		<limit effort="1" upper="-3.1415" lower="3.1415" velocity="1"/>
		<origin rpy="11.732836804848121 5.048527159697937 3.393981427221651" xyz="0.5127213343181469 0.10629285425074997 0.63826820322367"/>
	</joint>
	<joint name="455_to_245" type="revolute">
		<parent link="245"/>
		<child link="455"/>
		<axis xyz="1 0 0"/>
		<limit effort="1" upper="-3.1415" lower="3.1415" velocity="1"/>
		<origin rpy="1.210251098073951 3.63012818266156 1.5900322297015883" xyz="0.6584528667977734 0.10496627348971621 0.19411505082504898"/>
	</joint>
	<joint name="556_to_455" type="revolute">
		<parent link="455"/>
		<child link="556"/>
		<axis xyz="1 0 0"/>
		<limit effort="1" upper="-3.1415" lower="3.1415" velocity="1"/>
		<origin rpy="5.866418402424061 5.048527159697937 3.393981427221651" xyz="0.5127213343181469 0.10629285425074997 0.63826820322367"/>
	</joint>
	<joint name="557_to_455" type="revolute">
		<parent link="455"/>
		<child link="557"/>
		<axis xyz="1 0 0"/>
		<limit effort="1" upper="-3.1415" lower="3.1415" velocity="1"/>
		<origin rpy="8.799627603636091 5.048527159697937 3.393981427221651" xyz="0.5127213343181469 0.10629285425074997 0.63826820322367"/>
	</joint>
	<joint name="558_to_455" type="revolute">
		<parent link="455"/>
		<child link="558"/>
		<axis xyz="1 0 0"/>
		<limit effort="1" upper="-3.1415" lower="3.1415" velocity="1"/>
		<origin rpy="11.732836804848121 5.048527159697937 3.393981427221651" xyz="0.5127213343181469 0.10629285425074997 0.63826820322367"/>
	</joint>
	<joint name="259_to_144" type="revolute">
		<parent link="144"/>
		<child link="259"/>
		<axis xyz="0 1 0"/>
		<limit effort="1" upper="-3.1415" lower="3.1415" velocity="1"/>
		<origin rpy="17.216471566802877 2.9386225977356184 3.6706140324167555" xyz="0.34604144637492684 0.9486809796451484 0.6204757887286447"/>
	</joint>
	<joint name="360_to_259" type="revolute">
		<parent link="259"/>
		<child link="360"/>
		<axis xyz="0 1 0"/>
		<limit effort="1" upper="-3.1415" lower="3.1415" velocity="1"/>
		<origin rpy="9.964080971456038 2.2778805616572106 2.9818501228947247" xyz="0.937859089294457 0.302460945118709 0.42483515932786386"/>
	</joint>
	<joint name="461_to_259" type="revolute">
		<parent link="259"/>
		<child link="461"/>
		<axis xyz="1 0 0"/>
		<limit effort="1" upper="-3.1415" lower="3.1415" velocity="1"/>
		<origin rpy="0.7261506588443705 3.63012818266156 1.5900322297015883" xyz="0.6584528667977734 0.10496627348971621 0.19411505082504898"/>
	</joint>
	<joint name="562_to_461" type="revolute">
		<parent link="461"/>
		<child link="562"/>
		<axis xyz="1 0 0"/>
		<limit effort="1" upper="-3.1415" lower="3.1415" velocity="1"/>
		<origin rpy="5.866418402424061 5.048527159697937 3.393981427221651" xyz="0.5127213343181469 0.10629285425074997 0.63826820322367"/>
	</joint>
	<joint name="563_to_461" type="revolute">
		<parent link="461"/>
		<child link="563"/>
		<axis xyz="1 0 0"/>
		<limit effort="1" upper="-3.1415" lower="3.1415" velocity="1"/>
		<origin rpy="8.799627603636091 5.048527159697937 3.393981427221651" xyz="0.5127213343181469 0.10629285425074997 0.63826820322367"/>
	</joint>
	<joint name="564_to_461" type="revolute">
		<parent link="461"/>
		<child link="564"/>
		<axis xyz="1 0 0"/>
		<limit effort="1" upper="-3.1415" lower="3.1415" velocity="1"/>
		<origin rpy="11.732836804848121 5.048527159697937 3.393981427221651" xyz="0.5127213343181469 0.10629285425074997 0.63826820322367"/>
	</joint>
	<joint name="465_to_259" type="revolute">
		<parent link="259"/>
		<child link="465"/>
		<axis xyz="1 0 0"/>
		<limit effort="1" upper="-3.1415" lower="3.1415" velocity="1"/>
		<origin rpy="0.9682008784591607 3.63012818266156 1.5900322297015883" xyz="0.6584528667977734 0.10496627348971621 0.19411505082504898"/>
	</joint>
	<joint name="566_to_465" type="revolute">
		<parent link="465"/>
		<child link="566"/>
		<axis xyz="1 0 0"/>
		<limit effort="1" upper="-3.1415" lower="3.1415" velocity="1"/>
		<origin rpy="5.866418402424061 5.048527159697937 3.393981427221651" xyz="0.5127213343181469 0.10629285425074997 0.63826820322367"/>
	</joint>
	<joint name="567_to_465" type="revolute">
		<parent link="465"/>
		<child link="567"/>
		<axis xyz="1 0 0"/>
		<limit effort="1" upper="-3.1415" lower="3.1415" velocity="1"/>
		<origin rpy="8.799627603636091 5.048527159697937 3.393981427221651" xyz="0.5127213343181469 0.10629285425074997 0.63826820322367"/>
	</joint>
	<joint name="568_to_465" type="revolute">
		<parent link="465"/>
		<child link="568"/>
		<axis xyz="1 0 0"/>
		<limit effort="1" upper="-3.1415" lower="3.1415" velocity="1"/>
		<origin rpy="11.732836804848121 5.048527159697937 3.393981427221651" xyz="0.5127213343181469 0.10629285425074997 0.63826820322367"/>
	</joint>
	<joint name="469_to_259" type="revolute">
		<parent link="259"/>
		<child link="469"/>
		<axis xyz="1 0 0"/>
		<limit effort="1" upper="-3.1415" lower="3.1415" velocity="1"/>
		<origin rpy="1.210251098073951 3.63012818266156 1.5900322297015883" xyz="0.6584528667977734 0.10496627348971621 0.19411505082504898"/>
	</joint>
	<joint name="570_to_469" type="revolute">
		<parent link="469"/>
		<child link="570"/>
		<axis xyz="1 0 0"/>
		<limit effort="1" upper="-3.1415" lower="3.1415" velocity="1"/>
		<origin rpy="5.866418402424061 5.048527159697937 3.393981427221651" xyz="0.5127213343181469 0.10629285425074997 0.63826820322367"/>
	</joint>
	<joint name="571_to_469" type="revolute">
		<parent link="469"/>
		<child link="571"/>
		<axis xyz="1 0 0"/>
		<limit effort="1" upper="-3.1415" lower="3.1415" velocity="1"/>
		<origin rpy="8.799627603636091 5.048527159697937 3.393981427221651" xyz="0.5127213343181469 0.10629285425074997 0.63826820322367"/>
	</joint>
	<joint name="572_to_469" type="revolute">
		<parent link="469"/>
		<child link="572"/>
		<axis xyz="1 0 0"/>
		<limit effort="1" upper="-3.1415" lower="3.1415" velocity="1"/>
		<origin rpy="11.732836804848121 5.048527159697937 3.393981427221651" xyz="0.5127213343181469 0.10629285425074997 0.63826820322367"/>
	</joint>
	<joint name="273_to_144" type="revolute">
		<parent link="144"/>
		<child link="273"/>
		<axis xyz="0 1 0"/>
		<limit effort="1" upper="-3.1415" lower="3.1415" velocity="1"/>
		<origin rpy="22.955295422403836 2.9386225977356184 3.6706140324167555" xyz="0.34604144637492684 0.9486809796451484 0.6204757887286447"/>
	</joint>
	<joint name="374_to_273" type="revolute">
		<parent link="273"/>
		<child link="374"/>
		<axis xyz="0 1 0"/>
		<limit effort="1" upper="-3.1415" lower="3.1415" velocity="1"/>
		<origin rpy="9.964080971456038 2.2778805616572106 2.9818501228947247" xyz="0.937859089294457 0.302460945118709 0.42483515932786386"/>
	</joint>
	<joint name="475_to_273" type="revolute">
		<parent link="273"/>
		<child link="475"/>
		<axis xyz="1 0 0"/>
		<limit effort="1" upper="-3.1415" lower="3.1415" velocity="1"/>
		<origin rpy="0.7261506588443705 3.63012818266156 1.5900322297015883" xyz="0.6584528667977734 0.10496627348971621 0.19411505082504898"/>
	</joint>
	<joint name="576_to_475" type="revolute">
		<parent link="475"/>
		<child link="576"/>
		<axis xyz="1 0 0"/>
		<limit effort="1" upper="-3.1415" lower="3.1415" velocity="1"/>
		<origin rpy="5.866418402424061 5.048527159697937 3.393981427221651" xyz="0.5127213343181469 0.10629285425074997 0.63826820322367"/>
	</joint>
	<joint name="577_to_475" type="revolute">
		<parent link="475"/>
		<child link="577"/>
		<axis xyz="1 0 0"/>
		<limit effort="1" upper="-3.1415" lower="3.1415" velocity="1"/>
		<origin rpy="8.799627603636091 5.048527159697937 3.393981427221651" xyz="0.5127213343181469 0.10629285425074997 0.63826820322367"/>
	</joint>
	<joint name="578_to_475" type="revolute">
		<parent link="475"/>
		<child link="578"/>
		<axis xyz="1 0 0"/>
		<limit effort="1" upper="-3.1415" lower="3.1415" velocity="1"/>
		<origin rpy="11.732836804848121 5.048527159697937 3.393981427221651" xyz="0.5127213343181469 0.10629285425074997 0.63826820322367"/>
	</joint>
	<joint name="479_to_273" type="revolute">
		<parent link="273"/>
		<child link="479"/>
		<axis xyz="1 0 0"/>
		<limit effort="1" upper="-3.1415" lower="3.1415" velocity="1"/>
		<origin rpy="0.9682008784591607 3.63012818266156 1.5900322297015883" xyz="0.6584528667977734 0.10496627348971621 0.19411505082504898"/>
	</joint>
	<joint name="580_to_479" type="revolute">
		<parent link="479"/>
		<child link="580"/>
		<axis xyz="1 0 0"/>
		<limit effort="1" upper="-3.1415" lower="3.1415" velocity="1"/>
		<origin rpy="5.866418402424061 5.048527159697937 3.393981427221651" xyz="0.5127213343181469 0.10629285425074997 0.63826820322367"/>
	</joint>
	<joint name="581_to_479" type="revolute">
		<parent link="479"/>
		<child link="581"/>
		<axis xyz="1 0 0"/>
		<limit effort="1" upper="-3.1415" lower="3.1415" velocity="1"/>
		<origin rpy="8.799627603636091 5.048527159697937 3.393981427221651" xyz="0.5127213343181469 0.10629285425074997 0.63826820322367"/>
	</joint>
	<joint name="582_to_479" type="revolute">
		<parent link="479"/>
		<child link="582"/>
		<axis xyz="1 0 0"/>
		<limit effort="1" upper="-3.1415" lower="3.1415" velocity="1"/>
		<origin rpy="11.732836804848121 5.048527159697937 3.393981427221651" xyz="0.5127213343181469 0.10629285425074997 0.63826820322367"/>
	</joint>
	<joint name="483_to_273" type="revolute">
		<parent link="273"/>
		<child link="483"/>
		<axis xyz="1 0 0"/>
		<limit effort="1" upper="-3.1415" lower="3.1415" velocity="1"/>
		<origin rpy="1.210251098073951 3.63012818266156 1.5900322297015883" xyz="0.6584528667977734 0.10496627348971621 0.19411505082504898"/>
	</joint>
	<joint name="584_to_483" type="revolute">
		<parent link="483"/>
		<child link="584"/>
		<axis xyz="1 0 0"/>
		<limit effort="1" upper="-3.1415" lower="3.1415" velocity="1"/>
		<origin rpy="5.866418402424061 5.048527159697937 3.393981427221651" xyz="0.5127213343181469 0.10629285425074997 0.63826820322367"/>
	</joint>
	<joint name="585_to_483" type="revolute">
		<parent link="483"/>
		<child link="585"/>
		<axis xyz="1 0 0"/>
		<limit effort="1" upper="-3.1415" lower="3.1415" velocity="1"/>
		<origin rpy="8.799627603636091 5.048527159697937 3.393981427221651" xyz="0.5127213343181469 0.10629285425074997 0.63826820322367"/>
	</joint>
	<joint name="586_to_483" type="revolute">
		<parent link="483"/>
		<child link="586"/>
		<axis xyz="1 0 0"/>
		<limit effort="1" upper="-3.1415" lower="3.1415" velocity="1"/>
		<origin rpy="11.732836804848121 5.048527159697937 3.393981427221651" xyz="0.5127213343181469 0.10629285425074997 0.63826820322367"/>
	</joint>
	<joint name="187_to_0" type="revolute">
		<parent link="0"/>
		<child link="187"/>
		<axis xyz="0 1 0"/>
		<limit effort="1" upper="-3.1415" lower="3.1415" velocity="1"/>
		<origin rpy="24.70967473081982 6.150867155797274 5.514166033265675" xyz="0.005096555782734602 0.11978472283039487 0.28889542575000915"/>
	</joint>
	<joint name="288_to_187" type="revolute">
		<parent link="187"/>
		<child link="288"/>
		<axis xyz="0 1 0"/>
		<limit effort="1" upper="-3.1415" lower="3.1415" velocity="1"/>
		<origin rpy="11.477647711201918 2.9386225977356184 3.6706140324167555" xyz="0.34604144637492684 0.9486809796451484 0.6204757887286447"/>
	</joint>
	<joint name="389_to_288" type="revolute">
		<parent link="288"/>
		<child link="389"/>
		<axis xyz="0 1 0"/>
		<limit effort="1" upper="-3.1415" lower="3.1415" velocity="1"/>
		<origin rpy="9.964080971456038 2.2778805616572106 2.9818501228947247" xyz="0.937859089294457 0.302460945118709 0.42483515932786386"/>
	</joint>
	<joint name="490_to_288" type="revolute">
		<parent link="288"/>
		<child link="490"/>
		<axis xyz="1 0 0"/>
		<limit effort="1" upper="-3.1415" lower="3.1415" velocity="1"/>
		<origin rpy="0.7261506588443705 3.63012818266156 1.5900322297015883" xyz="0.6584528667977734 0.10496627348971621 0.19411505082504898"/>
	</joint>
	<joint name="591_to_490" type="revolute">
		<parent link="490"/>
		<child link="591"/>
		<axis xyz="1 0 0"/>
		<limit effort="1" upper="-3.1415" lower="3.1415" velocity="1"/>
		<origin rpy="5.866418402424061 5.048527159697937 3.393981427221651" xyz="0.5127213343181469 0.10629285425074997 0.63826820322367"/>
	</joint>
	<joint name="592_to_490" type="revolute">
		<parent link="490"/>
		<child link="592"/>
		<axis xyz="1 0 0"/>
		<limit effort="1" upper="-3.1415" lower="3.1415" velocity="1"/>
		<origin rpy="8.799627603636091 5.048527159697937 3.393981427221651" xyz="0.5127213343181469 0.10629285425074997 0.63826820322367"/>
	</joint>
	<joint name="593_to_490" type="revolute">
		<parent link="490"/>
		<child link="593"/>
		<axis xyz="1 0 0"/>
		<limit effort="1" upper="-3.1415" lower="3.1415" velocity="1"/>
		<origin rpy="11.732836804848121 5.048527159697937 3.393981427221651" xyz="0.5127213343181469 0.10629285425074997 0.63826820322367"/>
	</joint>
	<joint name="494_to_288" type="revolute">
		<parent link="288"/>
		<child link="494"/>
		<axis xyz="1 0 0"/>
		<limit effort="1" upper="-3.1415" lower="3.1415" velocity="1"/>
		<origin rpy="0.9682008784591607 3.63012818266156 1.5900322297015883" xyz="0.6584528667977734 0.10496627348971621 0.19411505082504898"/>
	</joint>
	<joint name="595_to_494" type="revolute">
		<parent link="494"/>
		<child link="595"/>
		<axis xyz="1 0 0"/>
		<limit effort="1" upper="-3.1415" lower="3.1415" velocity="1"/>
		<origin rpy="5.866418402424061 5.048527159697937 3.393981427221651" xyz="0.5127213343181469 0.10629285425074997 0.63826820322367"/>
	</joint>
	<joint name="596_to_494" type="revolute">
		<parent link="494"/>
		<child link="596"/>
		<axis xyz="1 0 0"/>
		<limit effort="1" upper="-3.1415" lower="3.1415" velocity="1"/>
		<origin rpy="8.799627603636091 5.048527159697937 3.393981427221651" xyz="0.5127213343181469 0.10629285425074997 0.63826820322367"/>
	</joint>
	<joint name="597_to_494" type="revolute">
		<parent link="494"/>
		<child link="597"/>
		<axis xyz="1 0 0"/>
		<limit effort="1" upper="-3.1415" lower="3.1415" velocity="1"/>
		<origin rpy="11.732836804848121 5.048527159697937 3.393981427221651" xyz="0.5127213343181469 0.10629285425074997 0.63826820322367"/>
	</joint>
	<joint name="498_to_288" type="revolute">
		<parent link="288"/>
		<child link="498"/>
		<axis xyz="1 0 0"/>
		<limit effort="1" upper="-3.1415" lower="3.1415" velocity="1"/>
		<origin rpy="1.210251098073951 3.63012818266156 1.5900322297015883" xyz="0.6584528667977734 0.10496627348971621 0.19411505082504898"/>
	</joint>
	<joint name="599_to_498" type="revolute">
		<parent link="498"/>
		<child link="599"/>
		<axis xyz="1 0 0"/>
		<limit effort="1" upper="-3.1415" lower="3.1415" velocity="1"/>
		<origin rpy="5.866418402424061 5.048527159697937 3.393981427221651" xyz="0.5127213343181469 0.10629285425074997 0.63826820322367"/>
	</joint>
	<joint name="5100_to_498" type="revolute">
		<parent link="498"/>
		<child link="5100"/>
		<axis xyz="1 0 0"/>
		<limit effort="1" upper="-3.1415" lower="3.1415" velocity="1"/>
		<origin rpy="8.799627603636091 5.048527159697937 3.393981427221651" xyz="0.5127213343181469 0.10629285425074997 0.63826820322367"/>
	</joint>
	<joint name="5101_to_498" type="revolute">
		<parent link="498"/>
		<child link="5101"/>
		<axis xyz="1 0 0"/>
		<limit effort="1" upper="-3.1415" lower="3.1415" velocity="1"/>
		<origin rpy="11.732836804848121 5.048527159697937 3.393981427221651" xyz="0.5127213343181469 0.10629285425074997 0.63826820322367"/>
	</joint>
	<joint name="2102_to_187" type="revolute">
		<parent link="187"/>
		<child link="2102"/>
		<axis xyz="0 1 0"/>
		<limit effort="1" upper="-3.1415" lower="3.1415" velocity="1"/>
		<origin rpy="17.216471566802877 2.9386225977356184 3.6706140324167555" xyz="0.34604144637492684 0.9486809796451484 0.6204757887286447"/>
	</joint>
	<joint name="3103_to_2102" type="revolute">
		<parent link="2102"/>
		<child link="3103"/>
		<axis xyz="0 1 0"/>
		<limit effort="1" upper="-3.1415" lower="3.1415" velocity="1"/>
		<origin rpy="9.964080971456038 2.2778805616572106 2.9818501228947247" xyz="0.937859089294457 0.302460945118709 0.42483515932786386"/>
	</joint>
	<joint name="4104_to_2102" type="revolute">
		<parent link="2102"/>
		<child link="4104"/>
		<axis xyz="1 0 0"/>
		<limit effort="1" upper="-3.1415" lower="3.1415" velocity="1"/>
		<origin rpy="0.7261506588443705 3.63012818266156 1.5900322297015883" xyz="0.6584528667977734 0.10496627348971621 0.19411505082504898"/>
	</joint>
	<joint name="5105_to_4104" type="revolute">
		<parent link="4104"/>
		<child link="5105"/>
		<axis xyz="1 0 0"/>
		<limit effort="1" upper="-3.1415" lower="3.1415" velocity="1"/>
		<origin rpy="5.866418402424061 5.048527159697937 3.393981427221651" xyz="0.5127213343181469 0.10629285425074997 0.63826820322367"/>
	</joint>
	<joint name="5106_to_4104" type="revolute">
		<parent link="4104"/>
		<child link="5106"/>
		<axis xyz="1 0 0"/>
		<limit effort="1" upper="-3.1415" lower="3.1415" velocity="1"/>
		<origin rpy="8.799627603636091 5.048527159697937 3.393981427221651" xyz="0.5127213343181469 0.10629285425074997 0.63826820322367"/>
	</joint>
	<joint name="5107_to_4104" type="revolute">
		<parent link="4104"/>
		<child link="5107"/>
		<axis xyz="1 0 0"/>
		<limit effort="1" upper="-3.1415" lower="3.1415" velocity="1"/>
		<origin rpy="11.732836804848121 5.048527159697937 3.393981427221651" xyz="0.5127213343181469 0.10629285425074997 0.63826820322367"/>
	</joint>
	<joint name="4108_to_2102" type="revolute">
		<parent link="2102"/>
		<child link="4108"/>
		<axis xyz="1 0 0"/>
		<limit effort="1" upper="-3.1415" lower="3.1415" velocity="1"/>
		<origin rpy="0.9682008784591607 3.63012818266156 1.5900322297015883" xyz="0.6584528667977734 0.10496627348971621 0.19411505082504898"/>
	</joint>
	<joint name="5109_to_4108" type="revolute">
		<parent link="4108"/>
		<child link="5109"/>
		<axis xyz="1 0 0"/>
		<limit effort="1" upper="-3.1415" lower="3.1415" velocity="1"/>
		<origin rpy="5.866418402424061 5.048527159697937 3.393981427221651" xyz="0.5127213343181469 0.10629285425074997 0.63826820322367"/>
	</joint>
	<joint name="5110_to_4108" type="revolute">
		<parent link="4108"/>
		<child link="5110"/>
		<axis xyz="1 0 0"/>
		<limit effort="1" upper="-3.1415" lower="3.1415" velocity="1"/>
		<origin rpy="8.799627603636091 5.048527159697937 3.393981427221651" xyz="0.5127213343181469 0.10629285425074997 0.63826820322367"/>
	</joint>
	<joint name="5111_to_4108" type="revolute">
		<parent link="4108"/>
		<child link="5111"/>
		<axis xyz="1 0 0"/>
		<limit effort="1" upper="-3.1415" lower="3.1415" velocity="1"/>
		<origin rpy="11.732836804848121 5.048527159697937 3.393981427221651" xyz="0.5127213343181469 0.10629285425074997 0.63826820322367"/>
	</joint>
	<joint name="4112_to_2102" type="revolute">
		<parent link="2102"/>
		<child link="4112"/>
		<axis xyz="1 0 0"/>
		<limit effort="1" upper="-3.1415" lower="3.1415" velocity="1"/>
		<origin rpy="1.210251098073951 3.63012818266156 1.5900322297015883" xyz="0.6584528667977734 0.10496627348971621 0.19411505082504898"/>
	</joint>
	<joint name="5113_to_4112" type="revolute">
		<parent link="4112"/>
		<child link="5113"/>
		<axis xyz="1 0 0"/>
		<limit effort="1" upper="-3.1415" lower="3.1415" velocity="1"/>
		<origin rpy="5.866418402424061 5.048527159697937 3.393981427221651" xyz="0.5127213343181469 0.10629285425074997 0.63826820322367"/>
	</joint>
	<joint name="5114_to_4112" type="revolute">
		<parent link="4112"/>
		<child link="5114"/>
		<axis xyz="1 0 0"/>
		<limit effort="1" upper="-3.1415" lower="3.1415" velocity="1"/>
		<origin rpy="8.799627603636091 5.048527159697937 3.393981427221651" xyz="0.5127213343181469 0.10629285425074997 0.63826820322367"/>
	</joint>
	<joint name="5115_to_4112" type="revolute">
		<parent link="4112"/>
		<child link="5115"/>
		<axis xyz="1 0 0"/>
		<limit effort="1" upper="-3.1415" lower="3.1415" velocity="1"/>
		<origin rpy="11.732836804848121 5.048527159697937 3.393981427221651" xyz="0.5127213343181469 0.10629285425074997 0.63826820322367"/>
	</joint>
	<joint name="2116_to_187" type="revolute">
		<parent link="187"/>
		<child link="2116"/>
		<axis xyz="0 1 0"/>
		<limit effort="1" upper="-3.1415" lower="3.1415" velocity="1"/>
		<origin rpy="22.955295422403836 2.9386225977356184 3.6706140324167555" xyz="0.34604144637492684 0.9486809796451484 0.6204757887286447"/>
	</joint>
	<joint name="3117_to_2116" type="revolute">
		<parent link="2116"/>
		<child link="3117"/>
		<axis xyz="0 1 0"/>
		<limit effort="1" upper="-3.1415" lower="3.1415" velocity="1"/>
		<origin rpy="9.964080971456038 2.2778805616572106 2.9818501228947247" xyz="0.937859089294457 0.302460945118709 0.42483515932786386"/>
	</joint>
	<joint name="4118_to_2116" type="revolute">
		<parent link="2116"/>
		<child link="4118"/>
		<axis xyz="1 0 0"/>
		<limit effort="1" upper="-3.1415" lower="3.1415" velocity="1"/>
		<origin rpy="0.7261506588443705 3.63012818266156 1.5900322297015883" xyz="0.6584528667977734 0.10496627348971621 0.19411505082504898"/>
	</joint>
	<joint name="5119_to_4118" type="revolute">
		<parent link="4118"/>
		<child link="5119"/>
		<axis xyz="1 0 0"/>
		<limit effort="1" upper="-3.1415" lower="3.1415" velocity="1"/>
		<origin rpy="5.866418402424061 5.048527159697937 3.393981427221651" xyz="0.5127213343181469 0.10629285425074997 0.63826820322367"/>
	</joint>
	<joint name="5120_to_4118" type="revolute">
		<parent link="4118"/>
		<child link="5120"/>
		<axis xyz="1 0 0"/>
		<limit effort="1" upper="-3.1415" lower="3.1415" velocity="1"/>
		<origin rpy="8.799627603636091 5.048527159697937 3.393981427221651" xyz="0.5127213343181469 0.10629285425074997 0.63826820322367"/>
	</joint>
	<joint name="5121_to_4118" type="revolute">
		<parent link="4118"/>
		<child link="5121"/>
		<axis xyz="1 0 0"/>
		<limit effort="1" upper="-3.1415" lower="3.1415" velocity="1"/>
		<origin rpy="11.732836804848121 5.048527159697937 3.393981427221651" xyz="0.5127213343181469 0.10629285425074997 0.63826820322367"/>
	</joint>
	<joint name="4122_to_2116" type="revolute">
		<parent link="2116"/>
		<child link="4122"/>
		<axis xyz="1 0 0"/>
		<limit effort="1" upper="-3.1415" lower="3.1415" velocity="1"/>
		<origin rpy="0.9682008784591607 3.63012818266156 1.5900322297015883" xyz="0.6584528667977734 0.10496627348971621 0.19411505082504898"/>
	</joint>
	<joint name="5123_to_4122" type="revolute">
		<parent link="4122"/>
		<child link="5123"/>
		<axis xyz="1 0 0"/>
		<limit effort="1" upper="-3.1415" lower="3.1415" velocity="1"/>
		<origin rpy="5.866418402424061 5.048527159697937 3.393981427221651" xyz="0.5127213343181469 0.10629285425074997 0.63826820322367"/>
	</joint>
	<joint name="5124_to_4122" type="revolute">
		<parent link="4122"/>
		<child link="5124"/>
		<axis xyz="1 0 0"/>
		<limit effort="1" upper="-3.1415" lower="3.1415" velocity="1"/>
		<origin rpy="8.799627603636091 5.048527159697937 3.393981427221651" xyz="0.5127213343181469 0.10629285425074997 0.63826820322367"/>
	</joint>
	<joint name="5125_to_4122" type="revolute">
		<parent link="4122"/>
		<child link="5125"/>
		<axis xyz="1 0 0"/>
		<limit effort="1" upper="-3.1415" lower="3.1415" velocity="1"/>
		<origin rpy="11.732836804848121 5.048527159697937 3.393981427221651" xyz="0.5127213343181469 0.10629285425074997 0.63826820322367"/>
	</joint>
	<joint name="4126_to_2116" type="revolute">
		<parent link="2116"/>
		<child link="4126"/>
		<axis xyz="1 0 0"/>
		<limit effort="1" upper="-3.1415" lower="3.1415" velocity="1"/>
		<origin rpy="1.210251098073951 3.63012818266156 1.5900322297015883" xyz="0.6584528667977734 0.10496627348971621 0.19411505082504898"/>
	</joint>
	<joint name="5127_to_4126" type="revolute">
		<parent link="4126"/>
		<child link="5127"/>
		<axis xyz="1 0 0"/>
		<limit effort="1" upper="-3.1415" lower="3.1415" velocity="1"/>
		<origin rpy="5.866418402424061 5.048527159697937 3.393981427221651" xyz="0.5127213343181469 0.10629285425074997 0.63826820322367"/>
	</joint>
	<joint name="5128_to_4126" type="revolute">
		<parent link="4126"/>
		<child link="5128"/>
		<axis xyz="1 0 0"/>
		<limit effort="1" upper="-3.1415" lower="3.1415" velocity="1"/>
		<origin rpy="8.799627603636091 5.048527159697937 3.393981427221651" xyz="0.5127213343181469 0.10629285425074997 0.63826820322367"/>
	</joint>
	<joint name="5129_to_4126" type="revolute">
		<parent link="4126"/>
		<child link="5129"/>
		<axis xyz="1 0 0"/>
		<limit effort="1" upper="-3.1415" lower="3.1415" velocity="1"/>
		<origin rpy="11.732836804848121 5.048527159697937 3.393981427221651" xyz="0.5127213343181469 0.10629285425074997 0.63826820322367"/>
	</joint>
</robot>
