<?xml version="1.0"?><robot name="pepe">
	<link name="0">
		<visual>
			<geometry>
				<cylinder length="1.9998" radius="0.4100438574956774"/>
			</geometry>
		</visual>
		<collision>
			<geometry>
				<cylinder length="1.9998" radius="0.4100438574956774"/>
			</geometry>
		</collision>
		<inertial>
			<mass value="1.0563237823933445"/>
			<inertia ixx="0.03" ixy="0" ixz="0" iyx="0" iyy="0.03" izz="0.03"/>
		</inertial>
	</link>
	<link name="11">
		<visual>
			<geometry>
				<cylinder length="0.2024734124825338" radius="0.4839424672611693"/>
			</geometry>
		</visual>
		<collision>
			<geometry>
				<cylinder length="0.2024734124825338" radius="0.4839424672611693"/>
			</geometry>
		</collision>
		<inertial>
			<mass value="0.14897223855170239"/>
			<inertia ixx="0.03" ixy="0" ixz="0" iyx="0" iyy="0.03" izz="0.03"/>
		</inertial>
	</link>
	<link name="12">
		<visual>
			<geometry>
				<cylinder length="0.2024734124825338" radius="0.4839424672611693"/>
			</geometry>
		</visual>
		<collision>
			<geometry>
				<cylinder length="0.2024734124825338" radius="0.4839424672611693"/>
			</geometry>
		</collision>
		<inertial>
			<mass value="0.14897223855170239"/>
			<inertia ixx="0.03" ixy="0" ixz="0" iyx="0" iyy="0.03" izz="0.03"/>
		</inertial>
	</link>
	<link name="13">
		<visual>
			<geometry>
				<cylinder length="0.2024734124825338" radius="0.4839424672611693"/>
			</geometry>
		</visual>
		<collision>
			<geometry>
				<cylinder length="0.2024734124825338" radius="0.4839424672611693"/>
			</geometry>
		</collision>
		<inertial>
			<mass value="0.14897223855170239"/>
			<inertia ixx="0.03" ixy="0" ixz="0" iyx="0" iyy="0.03" izz="0.03"/>
		</inertial>
	</link>
	<joint name="11_to_0" type="revolute">
		<parent link="0"/>
		<child link="11"/>
		<axis xyz="0 0 1"/>
		<limit effort="1" lower="3.1415" upper="-3.1415" velocity="1"/>
		<origin rpy="12.277245561587007 5.66721228121419 3.2352878676311425" xyz="0.4395348609760371 0.5167789386225082 0.8235360944058471"/>
	</joint>
	<joint name="12_to_0" type="revolute">
		<parent link="0"/>
		<child link="12"/>
		<axis xyz="0 0 1"/>
		<limit effort="1" lower="3.1415" upper="-3.1415" velocity="1"/>
		<origin rpy="18.41586834238051 5.66721228121419 3.2352878676311425" xyz="0.4395348609760371 0.5167789386225082 0.8235360944058471"/>
	</joint>
	<joint name="13_to_0" type="revolute">
		<parent link="0"/>
		<child link="13"/>
		<axis xyz="0 0 1"/>
		<limit effort="1" lower="3.1415" upper="-3.1415" velocity="1"/>
		<origin rpy="24.554491123174014 5.66721228121419 3.2352878676311425" xyz="0.4395348609760371 0.5167789386225082 0.8235360944058471"/>
	</joint>
</robot>
